Workbook

Sheet Summary
B2: Clarkson PLC (LSE: CKN) — Correlation & Regression: Segment Revenue vs Operating Profit
B3: Applies the correlation & simple-regression formulas from EXC 3672 Analyses of Financial Data (sample correlation r, OLS beta_hat/alpha_hat, R^2, standard error s_b, t-test, 95% CI) to the segment Revenue/Operating Profit panel, formalizing the flow-through-margin analysis in Clarksons_Margin_BalanceSheet_Analysis.docx §3.4.
B5: 1. Per-segment flow-through margin (beta_hat) — Operating Profit ~ Revenue, n=4 each
B6: Segment | C6: r | D6: R² | E6: beta_hat (flow-through) | F6: 95% CI | G6: p-value | H6: Result
B7: Broking | C7: =Regression!B24 -> 0.98207199 | D7: =Regression!B23 -> 0.9644654 | E7: =Regression!B20 -> 0.2413646 | F7: =Regression!B30&" - "&Regression!B31 -> 0.10041064769683 - 0.38231854896366 | G7: =Regression!B28 -> 0.017928006 | H7: p<0.05, significant
B8: Financial | C8: =Regression!B61 -> 0.88271761 | D8: =Regression!B60 -> 0.77919037 | E8: =Regression!B57 -> 0.29588563 | F8: =Regression!B67&" - "&Regression!B68 -> -0.18333155116352 - 0.775102805771111 | G8: =Regression!B65 -> 0.11728239 | H8: not significant
B9: Support | C9: =Regression!B98 -> 0.80508096 | D9: =Regression!B97 -> 0.64815535 | E9: =Regression!B94 -> 0.10838718 | F9: =Regression!B104&" - "&Regression!B105 -> -0.13457302306748 - 0.351347386703344 | G9: =Regression!B102 -> 0.19491904 | H9: not significant
B10: Research | C10: =Regression!B135 -> 0.99732493 | D10: =Regression!B134 -> 0.99465701 | E10: =Regression!B131 -> 0.37435416 | F10: =Regression!B141&" - "&Regression!B142 -> 0.290878551846801 - 0.457829761915529 | G10: =Regression!B139 -> 0.0026750744 | H10: p<0.05, significant
B12: Reading: beta_hat is the marginal £ of operating profit generated (or lost) per £1 of revenue change, estimated across all 4 available periods per segment (not a single two-point ratio). Broking and Research are statistically significant at 5%; Financial and Support are not (df=2, too few periods to separate a real slope from noise at conventional confidence — see Limitations).
B14: 2. Does segment SIZE predict MARGIN? (cross-sectional, n=4) — formalizes the earlier qualitative note
B15: r = -0.136, R² = 0.019, p = 0.86 (NOT significant). The earlier informal observation that "margin ranking is the exact opposite of revenue-size ranking" is a true statement about the ORDERING of 4 segments, but the underlying linear correlation is weak and statistically indistinguishable from zero — Research's very high margin is doing most of the work, not a general size-margin relationship. With only 4 segments (df=2), almost any ranking pattern can appear "opposite" by chance; the r/p-value is the more defensible claim than the ranking alone.
B18: 3. Existing two-point flow-through ratio vs regression estimate (Broking)
B19: Method | C19: Estimate | D19: Basis
B20: Old: FY24→FY25 ratio (revenue decline) | C20: 53.8% | D20: single pair of points, no uncertainty measure
B21: Old: H1'25→H1'26 ratio (revenue increase) | C21: 26.1% | D21: single pair of points, no uncertainty measure
B22: New: OLS regression (all 4 periods) | C22: 24.1% [95% CI: 10.0% - 38.2%] | D22: uses every available data point + quantifies uncertainty
B24: The two old point-to-point ratios disagree by a factor of 2x (53.8% vs 26.1%) purely because they used different pairs of periods — neither is "wrong", but neither is reliable alone. The regression estimate pools all 4 periods into one slope and reports how uncertain that slope is; its CI [10.0%, 38.2%] comfortably spans both old ratios, so the two are consistent with (not contradicting) the regression once sampling uncertainty is accounted for — they were never really two different numbers, just two noisy draws from the same underlying relationship.
B98: Limitations
B99: - Per-segment regressions use n=4 (df=2): with so few points, standard errors are wide and non-significant results (Financial, Support) mean "cannot rule out no relationship", not "no relationship" — this is exactly the small-sample-size problem the course covers in Week 5 ("what affects the accuracy of beta_hat"). - The pooled regression (n=16) pools all 4 segments together; its very high R²=0.979 is driven mostly by the large BETWEEN-segment differences in scale (Broking is ~15-20x the size of Research), not by how each segment's profit moves period to period. It should not be read as "a 1% revenue change anywhere in the group produces a 21.6% profit change" — that number is dominated by cross-segment size, not within-segment dynamics. - FY figures (FY2024, FY2025) and half-year figures (H1 2025, H1 2026) are mixed in the same regression; they are not independent (FY = H1 + H2 of the same year), which understates true variability slightly. - FY2024/FY2025 are audited; H1 2025/H1 2026 are reviewed, not audited (see Clarksons_Margin_BalanceSheet_Analysis.docx §5). - OLS assumes one constant slope across both revenue increases and decreases; the old ratios hint at possible cost stickiness (costs falling less than they rise) which a single linear beta cannot capture with only 4 points.

Sheet Data
A1: Clarkson PLC (LSE: CKN) — Correlation & Regression Analysis: Source Data
A2: Segment Revenue & Operating Profit panel, same figures as Clarksons_Operating_Profit_Structure.xlsx "Data" sheet. Source: Clarkson PLC 2025 Annual Report Note 4 "Segmental information" (FY2024/FY2025, audited); Interim Results Announcement 2026 Note 3 "Segmental information" (H1 2025/H1 2026, reviewed not audited).
A4: Segment | B4: Period | C4: Period Type | D4: Revenue (£m) | E4: Op. Profit (£m) | F4: Op. Margin (%)
A5: Broking | B5: FY2024 | C5: FY | D5: 529.3 | E5: 122.6 | F5: =E5/D5 -> 0.23162668
A6: Broking | B6: FY2025 | C6: FY | D6: 476 | E6: 93.9 | F6: =E6/D6 -> 0.19726891
A7: Broking | B7: H1 2025 | C7: H1 | D7: 222.2 | E7: 41.8 | F7: =E7/D7 -> 0.18811881
A8: Broking | B8: H1 2026 | C8: H1 | D8: 310.3 | E8: 64.8 | F8: =E8/D8 -> 0.20883016
A9: Financial | B9: FY2024 | C9: FY | D9: 42.6 | E9: 5.2 | F9: =E9/D9 -> 0.12206573
A10: Financial | B10: FY2025 | C10: FY | D10: 60.1 | E10: 12.9 | F10: =E10/D10 -> 0.21464226
A11: Financial | B11: H1 2025 | C11: H1 | D11: 28.9 | E11: 4.5 | F11: =E11/D11 -> 0.15570934
A12: Financial | B12: H1 2026 | C12: H1 | D12: 48.1 | E12: 11.7 | F12: =E12/D12 -> 0.24324324
A13: Support | B13: FY2024 | C13: FY | D13: 65 | E13: 7.7 | F13: =E13/D13 -> 0.11846154
A14: Support | B14: FY2025 | C14: FY | D14: 68.1 | E14: 4.8 | F14: =E14/D14 -> 0.070484581
A15: Support | B15: H1 2025 | C15: H1 | D15: 33.6 | E15: 2.9 | F15: =E15/D15 -> 0.086309524
A16: Support | B16: H1 2026 | C16: H1 | D16: 40 | E16: 2.6 | F16: =E16/D16 -> 0.065
... A20: Research | B20: H1 2026 | C20: H1 | D20: 15.1 | E20: 6.3 | F20: =E20/D20 -> 0.41721854
A23: Segment Averages (across the 4 periods) — used for the size-vs-margin cross-sectional test
A24: Segment | B24: Avg Revenue (£m) | C24: Avg Op. Margin (%)
A25: Broking | B25: =AVERAGEIF($A$5:$A$20,A25,$D$5:$D$20) -> 384.45 | C25: =AVERAGEIF($A$5:$A$20,A25,$F$5:$F$20) -> 0.20646114
A26: Financial | B26: =AVERAGEIF($A$5:$A$20,A26,$D$5:$D$20) -> 44.925 | C26: =AVERAGEIF($A$5:$A$20,A26,$F$5:$F$20) -> 0.18391514
A27: Support | B27: =AVERAGEIF($A$5:$A$20,A27,$D$5:$D$20) -> 51.675 | C27: =AVERAGEIF($A$5:$A$20,A27,$F$5:$F$20) -> 0.085063911
A28: Research | B28: =AVERAGEIF($A$5:$A$20,A28,$D$5:$D$20) -> 19.975 | C28: =AVERAGEIF($A$5:$A$20,A28,$F$5:$F$20) -> 0.39599813

Sheet Regression
A1: Clarkson PLC — Correlation & Simple Regression (AoFD course formulas, BI Norwegian Business School)
A2: Every statistic below is built from raw sums exactly as taught in Week 2 (sample correlation r), Week 4 (OLS estimators alpha_hat, beta_hat, R^2) and Week 5 (standard error s_b, t-test of H0: beta=0, 95% CI) of EXC 3672 Analyses of Financial Data. Cross-checked against Excel's built-in CORREL/SLOPE/INTERCEPT/RSQ/STEYX.
A4: Broking — Operating Profit ~ Revenue (n=4 periods, df=2)
A5: Period | B5: Revenue (£m) | C5: Op.Profit (£m) | D5: Xi-Xbar | E5: Yi-Ybar | F5: (Xi-Xbar)(Yi-Ybar) | G5: (Xi-Xbar)^2 | H5: (Yi-Ybar)^2 | I5: Yhat_i | J5: Residual | K5: Residual^2
A6: =Data!B5 -> FY2024 | B6: =Data!D5 -> 529.3 | C6: =Data!E5 -> 122.6 | D6: =B6-$B$14 -> 144.85 | E6: =C6-$B$15 -> 41.825 | F6: =D6*E6 -> 6058.3512 | G6: =D6^2 -> 20981.522 | H6: =E6^2 -> 1749.3306 | I6: =$B$19+$B$20*B6 -> 115.73666 | J6: =C6-I6 -> 6.8633379 | K6: =J6^2 -> 47.105408
A7: =Data!B6 -> FY2025 | B7: =Data!D6 -> 476 | C7: =Data!E6 -> 93.9 | D7: =B7-$B$14 -> 91.55 | E7: =C7-$B$15 -> 13.125 | F7: =D7*E7 -> 1201.5938 | G7: =D7^2 -> 8381.4025 | H7: =E7^2 -> 172.26562 | I7: =$B$19+$B$20*B7 -> 102.87193 | J7: =C7-I7 -> -8.971929 | K7: =J7^2 -> 80.49551
A8: =Data!B7 -> H1 2025 | B8: =Data!D7 -> 222.2 | C8: =Data!E7 -> 41.8 | D8: =B8-$B$14 -> -162.25 | E8: =C8-$B$15 -> -38.975 | F8: =D8*E8 -> 6323.6938 | G8: =D8^2 -> 26325.062 | H8: =E8^2 -> 1519.0506 | I8: =$B$19+$B$20*B8 -> 41.613594 | J8: =C8-I8 -> 0.18640608 | K8: =J8^2 -> 0.034747226
A9: =Data!B8 -> H1 2026 | B9: =Data!D8 -> 310.3 | C9: =Data!E8 -> 64.8 | D9: =B9-$B$14 -> -74.15 | E9: =C9-$B$15 -> -15.975 | F9: =D9*E9 -> 1184.5463 | G9: =D9^2 -> 5498.2225 | H9: =E9^2 -> 255.20063 | I9: =$B$19+$B$20*B9 -> 62.877815 | J9: =C9-I9 -> 1.922185 | K9: =J9^2 -> 3.694795
A10: Sum | F10: =SUM(F6:F9) -> 14768.185 | G10: =SUM(G6:G9) -> 61186.21 | H10: =SUM(H6:H9) -> 3695.8475 | K10: =SUM(K6:K9) -> 131.33046
A12: Regression results (Week 4-5 formulas)
A13: n | B13: =COUNT(B6:B9) -> 4 | C13: COUNT(X)
A14: Xbar | B14: =AVERAGE(B6:B9) -> 384.45 | C14: AVERAGE(X)
A15: Ybar | B15: =AVERAGE(C6:C9) -> 80.775 | C15: AVERAGE(Y)
A16: Sxx | B16: =G10 -> 61186.21 | C16: sum(Xi-Xbar)^2
A17: Sxy | B17: =F10 -> 14768.185 | C17: sum(Xi-Xbar)(Yi-Ybar)
A18: Syy | B18: =H10 -> 3695.8475 | C18: sum(Yi-Ybar)^2
A19: alpha_hat | B19: =B15-B20*B14 -> -12.01762 | C19: Ybar-beta_hat*Xbar
A20: beta_hat | B20: =B17/B16 -> 0.2413646 | C20: Sxy/Sxx <- OLS slope (Week 4 slide 12)
A21: TSS | B21: =B18 -> 3695.8475 | C21: Syy
A22: SSR | B22: =K10 -> 131.33046 | C22: sum(residual^2)
A23: R2 | B23: =1-B22/B21 -> 0.9644654 | C23: 1-SSR/TSS (Week 4 slide 16)
A24: r | B24: =B17/SQRT(B16*B18) -> 0.98207199 | C24: Sxy/SQRT(Sxx*Syy) (Week 2 slide 20)
A25: s_b | B25: =SQRT(B22/((B13-2)*B16)) -> 0.032759779 | C25: SQRT(SSR/((n-2)*Sxx)) (Week 5 slide 10)
A26: df | B26: =B13-2 -> 2 | C26: n-2
A27: t_stat | B27: =B20/B25 -> 7.3677115 | C27: beta_hat/s_b (H0: beta=0)
A28: p_value | B28: =TDIST(ABS(B27),B26,2) -> 0.017928006 | C28: TDIST(|t|,df,2-tail) | D28: =IF(B28<0.05,"significant at 5%",IF(B28<0.1,"significant at 10%","NOT significant at 10%")) -> significant at 5%
A29: t_crit | B29: =TINV(0.05,B26) -> 4.3026527 | C29: TINV(0.05,df), 95% CI
A30: CI_lo | B30: =B20-B29*B25 -> 0.10041065 | C30: beta_hat - t_crit*s_b
A31: CI_hi | B31: =B20+B29*B25 -> 0.38231855 | C31: beta_hat + t_crit*s_b
A33: Cross-check (Excel built-in functions)
A34: r_check(CORREL) | B34: =CORREL(C6:C9,B6:B9) -> 0.98207199
A35: beta_check(SLOPE) | B35: =SLOPE(C6:C9,B6:B9) -> 0.2413646
A36: alpha_check(INTERCEPT) | B36: =INTERCEPT(C6:C9,B6:B9) -> -12.01762
A37: R2_check(RSQ) | B37: =RSQ(C6:C9,B6:B9) -> 0.9644654
A38: s_b_check(STEYX) | B38: =STEYX(C6:C9,B6:B9)/SQRT(B16) -> 0.032759779
A41: Financial — Operating Profit ~ Revenue (n=4 periods, df=2)
A42: Period | B42: Revenue (£m) | C42: Op.Profit (£m) | D42: Xi-Xbar | E42: Yi-Ybar | F42: (Xi-Xbar)(Yi-Ybar) | G42: (Xi-Xbar)^2 | H42: (Yi-Ybar)^2 | I42: Yhat_i | J42: Residual | K42: Residual^2
A43: =Data!B9 -> FY2024 | B43: =Data!D9 -> 42.6 | C43: =Data!E9 -> 5.2 | D43: =B43-$B$51 -> -2.325 | E43: =C43-$B$52 -> -3.375 | F43: =D43*E43 -> 7.846875 | G43: =D43^2 -> 5.405625 | H43: =E43^2 -> 11.390625 | I43: =$B$56+$B$57*B43 -> 7.8870659 | J43: =C43-I43 -> -2.6870659 | K43: =J43^2 -> 7.2203232
A44: =Data!B10 -> FY2025 | B44: =Data!D10 -> 60.1 | C44: =Data!E10 -> 12.9 | D44: =B44-$B$51 -> 15.175 | E44: =C44-$B$52 -> 4.325 | F44: =D44*E44 -> 65.631875 | G44: =D44^2 -> 230.28062 | H44: =E44^2 -> 18.705625 | I44: =$B$56+$B$57*B44 -> 13.065064 | J44: =C44-I44 -> -0.16506439 | K44: =J44^2 -> 0.027246254
A45: =Data!B11 -> H1 2025 | B45: =Data!D11 -> 28.9 | C45: =Data!E11 -> 4.5 | D45: =B45-$B$51 -> -16.025 | E45: =C45-$B$52 -> -4.075 | F45: =D45*E45 -> 65.301875 | G45: =D45^2 -> 256.80063 | H45: =E45^2 -> 16.605625 | I45: =$B$56+$B$57*B45 -> 3.8334328 | J45: =C45-I45 -> 0.66656718 | K45: =J45^2 -> 0.4443118
...
