Workbook

Sheet Summary
A1: Clarkson PLC (LSE: CKN) — FY2026E Scenario Comparison
A2: All figures link to the Base Case, Bull Case and Bear Case sheets. Change a yellow input cell there and this sheet updates.
A3: FY2026E Summary (£m unless noted)
A4: Metric | B4: Base Case | C4: Bull Case | D4: Bear Case | E4: Spread (Bull − Bear)
A5: Revenue | B5: ='Base Case'!E6 -> 872.11983 | C5: ='Bull Case'!E6 -> 913.21318 | D5: ='Bear Case'!E6 -> 801.986 | E5: =C5-D5 -> 111.22718
A6: Underlying Operating Profit | B6: ='Base Case'!E9 -> 126.9105 | C6: ='Bull Case'!E9 -> 139.46181 | D6: ='Bear Case'!E9 -> 94.226903 | E6: =C6-D6 -> 45.234908
A7: Underlying Operating Margin % | B7: ='Base Case'!E10 -> 0.14551957 | C7: ='Bull Case'!E10 -> 0.1527155 | D7: ='Bear Case'!E10 -> 0.11749195 | E7: =C7-D7 -> 0.035223548
A8: Underlying Net Income | B8: ='Base Case'!E15 -> 104.27753 | C8: ='Bull Case'!E15 -> 113.87928 | D8: ='Bear Case'!E15 -> 79.27458 | E8: =C8-D8 -> 34.604704
A9: NOPAT | B9: ='Base Case'!E16 -> 97.086534 | C9: ='Bull Case'!E16 -> 106.68828 | D9: ='Bear Case'!E16 -> 72.08358 | E9: =C9-D9 -> 34.604704
A10: Real DSO, Dec 2026E (days) | B10: ='Base Case'!D20 -> 81.474002 | C10: ='Bull Case'!D20 -> 81.474002 | D10: ='Bear Case'!D20 -> 81.474002 | E10: =C10-D10 -> 0
A11: ECL Allowance, Dec 2026E | B11: ='Base Case'!D27 -> 39 | C11: ='Bull Case'!D27 -> 40.8 | D11: ='Bear Case'!D27 -> 42.8 | E11: =C11-D11 -> -2
A12: ECL charge / H2 revenue | B12: ='Base Case'!D28 -> 0.016789505 | C12: ='Bull Case'!D28 -> 0.019010905 | D12: ='Bear Case'!D28 -> 0.029602096 | E12: =C12-D12 -> -0.010591191
A13: Net Cash & Available Funds, Dec 2026E | B13: ='Base Case'!D40 -> 223.68698 | C13: ='Bull Case'!D40 -> 224.75784 | D13: ='Bear Case'!D40 -> 204.27903 | E13: =C13-D13 -> 20.478806
A14: Average Invested Capital, FY2026 | B14: ='Base Case'!D46 -> 345.11076 | C14: ='Bull Case'!D46 -> 347.24349 | D14: ='Bear Case'!D46 -> 343.71201 | E14: =C14-D14 -> 3.5314745
A15: ROIC FY2026E | B15: ='Base Case'!D47 -> 0.28131992 | C15: ='Bull Case'!D47 -> 0.30724344 | D15: ='Bear Case'!D47 -> 0.20972086 | E15: =C15-D15 -> 0.097522579
A17: Model Notes & Caveats
A18: 1. Structure: Broking H2 growth is built in two layers (Base and Bull sheets, rows 74-87). Layer 1 follows the Board's guidance of 31 July 2026 (no second-half weighting): organic Broking revenue flat, plus a full half of Link. Layer 2 adds the Yemen–Saudi escalation from 9 September 2026, for Broking only. Financial H2 growth is a separate input (Base 0% so the record H1 is not extrapolated; Bull +8%, the FY2025 H2 vs H1 change). Bear does not use the two layers. Head office costs are held at the H1 2026 actual (£28.6m) because no driver is disclosed for the H1 increase (+32.4% YoY).
A19: 2. Net finance income is held at £4.7m (H1 2026 level) in all scenarios and periods, to avoid a circular link with the cash forecast. A fuller model would tie it to average net cash.
A20: 3. The net assets roll-forward (row 42 on each sheet) leaves out OCI, FX translation and NCI movements to keep it simple.
A21: 4. The main judgments to test: segment H2 growth rates and flow-through choices, the Layer 2 weight (B86: Base 0.5, Bull 1.0), the H2 credit loss charge (B26; the part above the H1 level of £7.7m is taken off H2 operating profit, row 65), H2 M&A spend (D36) and the GBP/USD path (B67). Real DSO, T+2 balances, ESOP, lease payments, head office costs and the cash conversion multiple are based on reported figures and are the same in all scenarios. Each scenario's change in receivables affects cash through D34.
A22: 5. The H2 2026 dividend (£10.8m) is the same in all scenarios because it is the interim dividend already declared (35p per share).
A23: 6. H1 2026, June 2026 and FY2025 figures come from the 2026 Interim Report and the 2025 Annual Report / Preliminary Results (page references in the cell comments).
A24: 7. Basis: operating profit is before acquisition-related costs, as in the segment note (segment results less head office costs; INT26 Note 3 p.25, AR2025 Note 4 p.82). H1 2026 was £56.8m on this basis and £51.0m statutory. H1 2026 acquisition-related costs were £5.8m in operating profit (amortisation £1.4m, transaction costs £0.9m, charges linked to acquisitions £3.5m; INT26 Note 4 p.25) plus £0.1m of interest, £5.9m before tax (INT26 p.19). They are not forecast for H2. They will continue: the Link escrow (£12.6m) and share awards (Link £4.1m, Zuma £1.9m) are expensed over four years, about £2.3m per half, and amortisation of the £38.1m of acquired intangibles comes on top. Statutory H2 profit will therefore be lower than shown.
A25: 8. Segment margins use flow-through margins (change in operating profit ÷ change in revenue, from my margin analysis and AR2024 for Financial's decline year). Margins therefore move with the revenue assumptions. Support's flow-through was negative in both periods observed, so faster Support growth lowers its margin.
A26: 9. Average invested capital (row 46) uses three points (Dec 2025, Jun 2026, Dec 2026E) so that the June 2026 step-up from acquisitions (371.0) is included. A two-point average would leave it out and overstate ROIC, by about 2.3pp in the Base case.
A27: 10. FX uses the company's own hedged sensitivity from the 2025 Annual Report (Note 27 p.93: a 5% stronger USD adds £5.6m to PBT, a 5% weaker USD takes off £5.1m), which is about 1.24% / 1.13% of FY2025 underlying PBT (£90.6m) per 1% move. It is applied to an assumed GBP/USD path for H2. This is an approximation: the company's figure is a translation effect in £, applied here as a % of H2 profit.
A28: 11. Bear H2 2026E group margin (about 9.6%) is below the lowest half-year margin reported (H1 2025: 32.7 ÷ 297.8 = 11.0%, INT26 p.19). FY2026E Bear is higher (about 11.8%) because it includes the record H1 2026. There is no separate severe-downside case.
... A34: H2 2026E Segment Snapshot (£m) — live links to rows 52-56 of each scenario sheet
A35: Segment / metric | B35: Base Case | C35: Bull Case | D35: Bear Case | E35: H1 2026A 📄
A36: Broking — H2 Revenue | B36: ='Base Case'!H52 -> 351.16283 | C36: ='Bull Case'!H52 -> 385.55518 | D36: ='Bear Case'!H52 -> 285.476 | E36: 310.3
A37: Broking — H2 Op Profit | B37: ='Base Case'!I52 -> 75.465198 | C37: ='Bull Case'!I52 -> 84.441602 | D37: ='Bear Case'!I52 -> 51.444688 | E37: 64.8
A38: Broking — H2 Margin | B38: ='Base Case'!J52 -> 0.21490087 | C38: ='Bull Case'!J52 -> 0.21901301 | D38: ='Bear Case'!J52 -> 0.1802067 | E38: 0.20883016
A39: Financial — H2 Revenue | B39: ='Base Case'!H53 -> 48.1 | C39: ='Bull Case'!H53 -> 51.948 | D39: ='Bear Case'!H53 -> 46.657 | E39: 48.1
A40: Financial — H2 Op Profit | B40: ='Base Case'!I53 -> 11.7 | C40: ='Bull Case'!I53 -> 13.39312 | D40: ='Bear Case'!I53 -> 10.353681 | E40: 11.7
A41: Financial — H2 Margin | B41: ='Base Case'!J53 -> 0.24324324 | C41: ='Bull Case'!J53 -> 0.25781782 | D41: ='Bear Case'!J53 -> 0.22191056 | E41: 0.24324324
A42: Support — H2 Revenue | B42: ='Base Case'!H54 -> 43.2 | C42: ='Bull Case'!H54 -> 45.6 | D42: ='Bear Case'!H54 -> 40.8 | E42: 40
A43: Support — H2 Op Profit | B43: ='Base Case'!I54 -> 2.4496 | C43: ='Bull Case'!I54 -> 2.6 | D43: ='Bear Case'!I54 -> 2.44 | E43: 2.6
A44: Support — H2 Margin | B44: ='Base Case'!J54 -> 0.056703704 | C44: ='Bull Case'!J54 -> 0.057017544 | D44: ='Bear Case'!J54 -> 0.059803922 | E44: 0.065
A45: Research — H2 Revenue | B45: ='Base Case'!H55 -> 16.157 | C45: ='Bull Case'!H55 -> 16.61 | D45: ='Bear Case'!H55 -> 15.553 | E45: 15.1
A46: Research — H2 Op Profit | B46: ='Base Case'!I55 -> 6.9342 | C46: ='Bull Case'!I55 -> 7.206 | D46: ='Bear Case'!I55 -> 6.484371 | E46: 6.3
...

Sheet Base Case
A1: Clarkson PLC (LSE: CKN) — H2 2026E / FY2026E Scenario Model: Base Case
A2: £m unless noted. Blue = input. Black = formula. Green = link to another sheet.
A3: Tags: 📄 = from the filings (page given in the comment); 🔵 = my assumption; 🔢 = calculation; 🌐 = news source, not in the filings.
A4: P&L Forecast (£m)
A5: Item | B5: Assumption | C5: H1 2026A 📄 | D5: H2 2026E | E5: FY2026E | F5: Note / Source
A6: Revenue | C6: 413.5 | D6: =H56 -> 458.61983 | E6: =C6+D6 -> 872.11983 | F6: H2 Revenue = Total Segment H2 2026E Revenue (row 56) — see segment detail below
A7: H2 revenue growth vs. H1 2026 (computed, from segment roll-up) | B7: =D6/C6-1 -> 0.10911688
A8: Underlying Operating Margin, H2 (computed, from segment + HO + FX roll-up) | B8: =D9/D6 -> 0.15287281
A9: Underlying Operating Profit | C9: 56.8 | D9: =D71 -> 70.110501 | E9: =C9+D9 -> 126.9105 | F9: From row 71 (group operating profit after head office costs, FX and extra credit losses). Before acquisition-related costs, like the H1 figure of 56.8 (Summary note 7).
A10: Implied Operating Margin % (check) | C10: =C9/C6 -> 0.13736397 | D10: =D9/D6 -> 0.15287281 | E10: =E9/E6 -> 0.14551957
A11: Net Finance Income (🔵 held constant — see model notes) | B11: 4.7 | C11: 4.7 | D11: =B11 -> 4.7 | E11: =C11+D11 -> 9.4 | F11: £4.7m = H1 2026 underlying PBT (61.5) − underlying operating profit (56.8). This matches the income statement: finance income 6.0, finance costs (1.7) and pension income 0.4 (INT26 p.19). Held flat in H2 and in all scenarios to avoid a circular link with cash (Summary note 2).
A12: Underlying Profit Before Tax | C12: =C9+C11 -> 61.5 | D12: =D9+D11 -> 74.810501 | E12: =C12+D12 -> 136.3105
A13: Tax rate (📄 INT26 Note 5 p.25: expected FY2026 rate excluding acquisition-related costs) | B13: 0.235
A14: Tax | C14: =C12*$B$13 -> 14.4525 | D14: =D12*$B$13 -> 17.580468 | E14: =C14+D14 -> 32.032968
A15: Underlying Net Income | C15: =C12-C14 -> 47.0475 | D15: =D12-D14 -> 57.230034 | E15: =E12-E14 -> 104.27753
A16: NOPAT (operating basis, for ROIC only) | C16: =C9*(1-$B$13) -> 43.452 | D16: =D9*(1-$B$13) -> 53.634534 | E16: =E9*(1-$B$13) -> 97.086534
A18: Receivables, DSO & Credit Losses (£m / days)
A19: Item | B19: Assumption | C19: Jun 2026A 📄 | D19: Dec 2026E | F19: Note / Source
A20: Real DSO (days, ex-T+2 settlement) | B20: =C20 -> 81.474002 | C20: =C22/(C6*2)*365 -> 81.474002 | D20: =B20 -> 81.474002 | F20: Same in all scenarios, at the H1 2026 actual: 184.6 ÷ 827.0 × 365 = 81.47 days (ex-settlement receivables ÷ annualised H1 revenue). There is no evidence that collection differs by scenario.
A21: T+2 Settlement Accounts (🔢 = Jun 2026A × (1 + Financial H2 growth, D53)) | B21: =C21*(1+D53) -> 84.2 | C21: 84.2 | D21: =B21 -> 84.2 | F21: The £84.2m of T+2 settlement balances sit in the Financial division and usually settle two days after the trade (INT26 Note 10 p.29). They are matched by an £84.1m payable, so they are a pass-through, not a credit risk. The balance grows with Financial H2 revenue (D53).
A22: Ex-settlement receivables (trade and other receivables less T+2; the interim balance sheet does not split trade and other) | C22: 184.6 | D22: =D20/365*E6 -> 194.67149 | F22: Dec26E uses FY2026E revenue (E6) — DSO convention per report §5-1
A23: Total Current Receivables | C23: =C21+C22 -> 268.8 | D23: =D21+D22 -> 278.87149
A24: Surface DSO (days, check) | C24: =C23/(C6*2)*365 -> 118.63603 | D24: =D23/E6*365 -> 116.71343
A25: ECL Allowance, opening balance | C25: 31.3
A26: H2 Net Impairment Loss / ECL charge (🔵 assumption) | B26: 7.7
A27: ECL Allowance, closing balance | D27: =C25+B26 -> 39
A28: ECL charge / H2 revenue | D28: =B26/D6 -> 0.016789505
A29: Allowance / Ex-Settlement Receivables (coverage) | C29: =C25/C22 -> 0.1695558 | D29: =D27/D22 -> 0.2003375
A31: Cash Flow & ROIC (£m)
A32: Item | B32: Assumption | C32: Jun 2026A 📄 | D32: Dec 2026E | F32: Note / Source
A33: Net Cash & Available Funds, opening | C33: 178.8
A34: H2 operating cash flow (🔢 = H2 op. profit × B34 − change in ex-settlement receivables, D22 − C22) | B34: =E115 -> 1.2472406 | D34: =D9*B34-(D22-C22) -> 77.373177 | F34: Formula: D9 × B34 − (D22 − C22). B34 is the H2 2025 conversion before working capital (about 1.25x, row 115). T+2 balances (row 21) are left out because they are matched by payables (INT26 Note 10 p.29).
A35: H2 CAPEX (% of H2 revenue, 🔵 assumption) | B35: 0.01 | D35: =D6*B35 -> 4.5861983
A36: H2 M&A spend (🔵 assumption) | D36: 10
A37: H2 Dividend paid (📄 disclosed: 2026 interim 35p = £10.8m) | D37: 10.8
A38: H2 ESOP buybacks (📄 anchored to H2 2025 actual, row 102) | D38: =E102 -> 1.8
A39: H2 Lease principal repayment (📄 held at H1 2026A actual) | D39: 5.3
A40: Net Cash & Available Funds, closing | D40: =C33+D34-D35-D36-D37-D38-D39 -> 223.68698
A41: Net Assets, opening (derived: Invested Capital + Net Cash) | C41: 549.8 | F41: Simplified: excludes OCI/FX/NCI — see model notes
A42: Net Assets, closing (simplified roll-forward) | D42: =C41+D15-D37-D38 -> 594.43003
...

Sheet Bull Case
A1: Clarkson PLC (LSE: CKN) — H2 2026E / FY2026E Scenario Model: Bull Case
A2: £m unless noted. Blue = input. Black = formula. Green = link to another sheet.
A3: Tags: 📄 = from the filings (page given in the comment); 🔵 = my assumption; 🔢 = calculation; 🌐 = news source, not in the filings.
A4: P&L Forecast (£m)
A5: Item | B5: Assumption | C5: H1 2026A 📄 | D5: H2 2026E | E5: FY2026E | F5: Note / Source
A6: Revenue | C6: 413.5 | D6: =H56 -> 499.71318 | E6: =C6+D6 -> 913.21318 | F6: H2 Revenue = Total Segment H2 2026E Revenue (row 56) — see segment detail below
A7: H2 revenue growth vs. H1 2026 (computed, from segment roll-up) | B7: =D6/C6-1 -> 0.20849621
A8: Underlying Operating Margin, H2 (computed, from segment + HO + FX roll-up) | B8: =D9/D6 -> 0.16541851
A9: Underlying Operating Profit | C9: 56.8 | D9: =D71 -> 82.66181 | E9: =C9+D9 -> 139.46181 | F9: From row 71 (group operating profit after head office costs, FX and extra credit losses). Before acquisition-related costs, like the H1 figure of 56.8 (Summary note 7).
A10: Implied Operating Margin % (check) | C10: =C9/C6 -> 0.13736397 | D10: =D9/D6 -> 0.16541851 | E10: =E9/E6 -> 0.1527155
A11: Net Finance Income (🔵 held constant — see model notes) | B11: 4.7 | C11: 4.7 | D11: =B11 -> 4.7 | E11: =C11+D11 -> 9.4 | F11: £4.7m = H1 2026 underlying PBT (61.5) − underlying operating profit (56.8). This matches the income statement: finance income 6.0, finance costs (1.7) and pension income 0.4 (INT26 p.19). Held flat in H2 and in all scenarios to avoid a circular link with cash (Summary note 2).
A12: Underlying Profit Before Tax | C12: =C9+C11 -> 61.5 | D12: =D9+D11 -> 87.36181 | E12: =C12+D12 -> 148.86181
A13: Tax rate (📄 INT26 Note 5 p.25: expected FY2026 rate excluding acquisition-related costs) | B13: 0.235
A14: Tax | C14: =C12*$B$13 -> 14.4525 | D14: =D12*$B$13 -> 20.530025 | E14: =C14+D14 -> 34.982525
A15: Underlying Net Income | C15: =C12-C14 -> 47.0475 | D15: =D12-D14 -> 66.831785 | E15: =E12-E14 -> 113.87928
A16: NOPAT (operating basis, for ROIC only) | C16: =C9*(1-$B$13) -> 43.452 | D16: =D9*(1-$B$13) -> 63.236285 | E16: =E9*(1-$B$13) -> 106.68828
A18: Receivables, DSO & Credit Losses (£m / days)
A19: Item | B19: Assumption | C19: Jun 2026A 📄 | D19: Dec 2026E | F19: Note / Source
A20: Real DSO (days, ex-T+2 settlement) | B20: =C20 -> 81.474002 | C20: =C22/(C6*2)*365 -> 81.474002 | D20: =B20 -> 81.474002 | F20: Same in all scenarios, at the H1 2026 actual: 184.6 ÷ 827.0 × 365 = 81.47 days (ex-settlement receivables ÷ annualised H1 revenue). There is no evidence that collection differs by scenario.
A21: T+2 Settlement Accounts (🔢 = Jun 2026A × (1 + Financial H2 growth, D53)) | B21: =C21*(1+D53) -> 90.936 | C21: 84.2 | D21: =B21 -> 90.936 | F21: The £84.2m of T+2 settlement balances sit in the Financial division and usually settle two days after the trade (INT26 Note 10 p.29). They are matched by an £84.1m payable, so they are a pass-through, not a credit risk. The balance grows with Financial H2 revenue (D53).
A22: Ex-settlement receivables (trade and other receivables less T+2; the interim balance sheet does not split trade and other) | C22: 184.6 | D22: =D20/365*E6 -> 203.8442 | F22: Dec26E uses FY2026E revenue (E6) — DSO convention per report §5-1
A23: Total Current Receivables | C23: =C21+C22 -> 268.8 | D23: =D21+D22 -> 294.7802
A24: Surface DSO (days, check) | C24: =C23/(C6*2)*365 -> 118.63603 | D24: =D23/E6*365 -> 117.82
A25: ECL Allowance, opening balance | C25: 31.3
A26: H2 Net Impairment Loss / ECL charge (🔵 assumption) | B26: 9.5
A27: ECL Allowance, closing balance | D27: =C25+B26 -> 40.8
A28: ECL charge / H2 revenue | D28: =B26/D6 -> 0.019010905
A29: Allowance / Ex-Settlement Receivables (coverage) | C29: =C25/C22 -> 0.1695558 | D29: =D27/D22 -> 0.20015286
A31: Cash Flow & ROIC (£m)
A32: Item | B32: Assumption | C32: Jun 2026A 📄 | D32: Dec 2026E | F32: Note / Source
A33: Net Cash & Available Funds, opening | C33: 178.8
A34: H2 operating cash flow (🔢 = H2 op. profit × B34 − change in ex-settlement receivables, D22 − C22) | B34: =E115 -> 1.2472406 | D34: =D9*B34-(D22-C22) -> 83.854967 | F34: Formula: D9 × B34 − (D22 − C22). B34 is the H2 2025 conversion before working capital (about 1.25x, row 115). T+2 balances (row 21) are left out because they are matched by payables (INT26 Note 10 p.29).
A35: H2 CAPEX (% of H2 revenue, 🔵 assumption) | B35: 0.01 | D35: =D6*B35 -> 4.9971318
A36: H2 M&A spend (🔵 assumption) | D36: 15
A37: H2 Dividend paid (📄 disclosed: 2026 interim 35p = £10.8m) | D37: 10.8
A38: H2 ESOP buybacks (📄 anchored to H2 2025 actual, row 102) | D38: =E102 -> 1.8
A39: H2 Lease principal repayment (📄 held at H1 2026A actual) | D39: 5.3
A40: Net Cash & Available Funds, closing | D40: =C33+D34-D35-D36-D37-D38-D39 -> 224.75784
A41: Net Assets, opening (derived: Invested Capital + Net Cash) | C41: 549.8 | F41: Simplified: excludes OCI/FX/NCI — see model notes
A42: Net Assets, closing (simplified roll-forward) | D42: =C41+D15-D37-D38 -> 604.03178
...

Sheet Bear Case
A1: Clarkson PLC (LSE: CKN) — H2 2026E / FY2026E Scenario Model: Bear Case
A2: £m unless noted. Blue = input. Black = formula. Green = link to another sheet.
A3: Tags: 📄 = from the filings (page given in the comment); 🔵 = my assumption; 🔢 = calculation; 🌐 = news source, not in the filings.
A4: P&L Forecast (£m)
A5: Item | B5: Assumption | C5: H1 2026A 📄 | D5: H2 2026E | E5: FY2026E | F5: Note / Source
A6: Revenue | C6: 413.5 | D6: =H56 -> 388.486 | E6: =C6+D6 -> 801.986 | F6: H2 Revenue = Total Segment H2 2026E Revenue (row 56) — see segment detail below
A7: H2 revenue growth vs. H1 2026 (computed, from segment roll-up) | B7: =D6/C6-1 -> -0.060493349
A8: Underlying Operating Margin, H2 (computed, from segment + HO + FX roll-up) | B8: =D9/D6 -> 0.096340415
A9: Underlying Operating Profit | C9: 56.8 | D9: =D71 -> 37.426903 | E9: =C9+D9 -> 94.226903 | F9: From row 71 (group operating profit after head office costs, FX and extra credit losses). Before acquisition-related costs, like the H1 figure of 56.8 (Summary note 7).
A10: Implied Operating Margin % (check) | C10: =C9/C6 -> 0.13736397 | D10: =D9/D6 -> 0.096340415 | E10: =E9/E6 -> 0.11749195
A11: Net Finance Income (🔵 held constant — see model notes) | B11: 4.7 | C11: 4.7 | D11: =B11 -> 4.7 | E11: =C11+D11 -> 9.4 | F11: £4.7m = H1 2026 underlying PBT (61.5) − underlying operating profit (56.8). This matches the income statement: finance income 6.0, finance costs (1.7) and pension income 0.4 (INT26 p.19). Held flat in H2 and in all scenarios to avoid a circular link with cash (Summary note 2).
A12: Underlying Profit Before Tax | C12: =C9+C11 -> 61.5 | D12: =D9+D11 -> 42.126903 | E12: =C12+D12 -> 103.6269
A13: Tax rate (📄 INT26 Note 5 p.25: expected FY2026 rate excluding acquisition-related costs) | B13: 0.235
A14: Tax | C14: =C12*$B$13 -> 14.4525 | D14: =D12*$B$13 -> 9.8998221 | E14: =C14+D14 -> 24.352322
A15: Underlying Net Income | C15: =C12-C14 -> 47.0475 | D15: =D12-D14 -> 32.22708 | E15: =E12-E14 -> 79.27458
A16: NOPAT (operating basis, for ROIC only) | C16: =C9*(1-$B$13) -> 43.452 | D16: =D9*(1-$B$13) -> 28.63158 | E16: =E9*(1-$B$13) -> 72.08358
A18: Receivables, DSO & Credit Losses (£m / days)
A19: Item | B19: Assumption | C19: Jun 2026A 📄 | D19: Dec 2026E | F19: Note / Source
A20: Real DSO (days, ex-T+2 settlement) | B20: =C20 -> 81.474002 | C20: =C22/(C6*2)*365 -> 81.474002 | D20: =B20 -> 81.474002 | F20: Same in all scenarios, at the H1 2026 actual: 184.6 ÷ 827.0 × 365 = 81.47 days (ex-settlement receivables ÷ annualised H1 revenue). There is no evidence that collection differs by scenario.
A21: T+2 Settlement Accounts (🔢 = Jun 2026A × (1 + Financial H2 growth, D53)) | B21: =C21*(1+D53) -> 81.674 | C21: 84.2 | D21: =B21 -> 81.674 | F21: The £84.2m of T+2 settlement balances sit in the Financial division and usually settle two days after the trade (INT26 Note 10 p.29). They are matched by an £84.1m payable, so they are a pass-through, not a credit risk. The balance grows with Financial H2 revenue (D53).
A22: Ex-settlement receivables (trade and other receivables less T+2; the interim balance sheet does not split trade and other) | C22: 184.6 | D22: =D20/365*E6 -> 179.01646 | F22: Dec26E uses FY2026E revenue (E6) — DSO convention per report §5-1
A23: Total Current Receivables | C23: =C21+C22 -> 268.8 | D23: =D21+D22 -> 260.69046
A24: Surface DSO (days, check) | C24: =C23/(C6*2)*365 -> 118.63603 | D24: =D23/E6*365 -> 118.64549
A25: ECL Allowance, opening balance | C25: 31.3
A26: H2 Net Impairment Loss / ECL charge (🔵 assumption) | B26: 11.5
A27: ECL Allowance, closing balance | D27: =C25+B26 -> 42.8
A28: ECL charge / H2 revenue | D28: =B26/D6 -> 0.029602096
A29: Allowance / Ex-Settlement Receivables (coverage) | C29: =C25/C22 -> 0.1695558 | D29: =D27/D22 -> 0.23908416
A31: Cash Flow & ROIC (£m)
A32: Item | B32: Assumption | C32: Jun 2026A 📄 | D32: Dec 2026E | F32: Note / Source
A33: Net Cash & Available Funds, opening | C33: 178.8
A34: H2 operating cash flow (🔢 = H2 op. profit × B34 − change in ex-settlement receivables, D22 − C22) | B34: =E115 -> 1.2472406 | D34: =D9*B34-(D22-C22) -> 52.263889 | F34: Formula: D9 × B34 − (D22 − C22). B34 is the H2 2025 conversion before working capital (about 1.25x, row 115). T+2 balances (row 21) are left out because they are matched by payables (INT26 Note 10 p.29).
A35: H2 CAPEX (% of H2 revenue, 🔵 assumption) | B35: 0.01 | D35: =D6*B35 -> 3.88486
A36: H2 M&A spend (🔵 assumption) | D36: 5
A37: H2 Dividend paid (📄 disclosed: 2026 interim 35p = £10.8m) | D37: 10.8
A38: H2 ESOP buybacks (📄 anchored to H2 2025 actual, row 102) | D38: =E102 -> 1.8
A39: H2 Lease principal repayment (📄 held at H1 2026A actual) | D39: 5.3
A40: Net Cash & Available Funds, closing | D40: =C33+D34-D35-D36-D37-D38-D39 -> 204.27903
A41: Net Assets, opening (derived: Invested Capital + Net Cash) | C41: 549.8 | F41: Simplified: excludes OCI/FX/NCI — see model notes
A42: Net Assets, closing (simplified roll-forward) | D42: =C41+D15-D37-D38 -> 569.42708
...

Sheet Scenario Charts
A1: Clarkson PLC — FY2026E Scenario Comparison Charts
A2: Data below links live to the Summary sheet.
A4: Revenue (£m) | D4: Profitability (£m)
A5: Scenario | B5: Revenue | D5: Scenario | E5: Operating Profit | F5: Net Income | G5: NOPAT
A6: Base Case | B6: =Summary!B5 -> 872.11983 | D6: Base Case | E6: =Summary!B6 -> 126.9105 | F6: =Summary!B8 -> 104.27753 | G6: =Summary!B9 -> 97.086534
A7: Bull Case | B7: =Summary!C5 -> 913.21318 | D7: Bull Case | E7: =Summary!C6 -> 139.46181 | F7: =Summary!C8 -> 113.87928 | G7: =Summary!C9 -> 106.68828
A8: Bear Case | B8: =Summary!D5 -> 801.986 | D8: Bear Case | E8: =Summary!D6 -> 94.226903 | F8: =Summary!D8 -> 79.27458 | G8: =Summary!D9 -> 72.08358
A10: Margins & Returns (%)
A11: Scenario | B11: Operating Margin % | C11: ROIC %
A12: Base Case | B12: =Summary!B7 -> 0.14551957 | C12: =Summary!B15 -> 0.28131992
A13: Bull Case | B13: =Summary!C7 -> 0.1527155 | C13: =Summary!C15 -> 0.30724344
A14: Bear Case | B14: =Summary!D7 -> 0.11749195 | C14: =Summary!D15 -> 0.20972086
