Workbook

Sheet Data
A1: Clarkson PLC (LSE: CKN) — Segment Revenue & Operating Profit Data
A3: Segment Revenue & Operating Profit (£m)
A4: Segment | B4: FY2024 Revenue | C4: FY2025 Revenue | D4: H1 2025 Revenue | E4: H1 2026 Revenue | F4: FY2024 Op Profit | G4: FY2025 Op Profit | H4: H1 2025 Op Profit | I4: H1 2026 Op Profit
A5: Broking | B5: 529.3 | C5: 476 | D5: 222.2 | E5: 310.3 | F5: 122.6 | G5: 93.9 | H5: 41.8 | I5: 64.8
A6: Financial | B6: 42.6 | C6: 60.1 | D6: 28.9 | E6: 48.1 | F6: 5.2 | G6: 12.9 | H6: 4.5 | I6: 11.7
A7: Support | B7: 65 | C7: 68.1 | D7: 33.6 | E7: 40 | F7: 7.7 | G7: 4.8 | H7: 2.9 | I7: 2.6
A8: Research | B8: 24.5 | C8: 27.2 | D8: 13.1 | E8: 15.1 | F8: 9.5 | G8: 10.6 | H8: 5.1 | I8: 6.3
A9: Segment Total | B9: =SUM(B5:B8) -> 661.4 | C9: =SUM(C5:C8) -> 631.4 | D9: =SUM(D5:D8) -> 297.8 | E9: =SUM(E5:E8) -> 413.5 | F9: =SUM(F5:F8) -> 145 | G9: =SUM(G5:G8) -> 122.2 | H9: =SUM(H5:H8) -> 54.3 | I9: =SUM(I5:I8) -> 85.4
A10: Head Office Costs | B10: n/a | C10: n/a | D10: n/a | E10: n/a | F10: -43.3 | G10: -44.2 | H10: -21.6 | I10: -28.6
A11: Group Total | B11: =B9 -> 661.4 | C11: =C9 -> 631.4 | D11: =D9 -> 297.8 | E11: =E9 -> 413.5 | F11: =F9+F10 -> 101.7 | G11: =G9+G10 -> 78 | H11: =H9+H10 -> 32.7 | I11: =I9+I10 -> 56.8
A12: Source: Clarkson PLC 2025 Annual Report, Note 4 "Segmental information" (FY2024/FY2025); Interim Results Announcement 2026, Note 3 "Segmental information" (H1 2025/H1 2026).
A15: Average Number of Employees by Segment
A16: Segment | B16: FY2024 Employees | C16: FY2025 Employees
A17: Broking | B17: 1402 | C17: 1504
A18: Financial | B18: 119 | C18: 127
A19: Support | B19: 432 | C19: 457
A20: Research | B20: 150 | C20: 167
A21: Total | B21: =SUM(B17:B20) -> 2103 | C21: =SUM(C17:C20) -> 2255
A22: Source: Clarkson PLC 2025 Annual Report, Note 3 (Employee costs), average monthly headcount by segment.
A25: Revenue by Geography — by Origin of Invoice (£m)
A26: Region | B26: FY2024 Revenue | C26: FY2025 Revenue
A27: Europe, Middle East and Africa | B27: 484.4 | C27: 469.4
A28: Americas | B28: 28.7 | C28: 23.4
A29: Asia-Pacific | B29: 148.3 | C29: 138.6
A30: Total | B30: =SUM(B27:B29) -> 661.4 | C30: =SUM(C27:C29) -> 631.4
A31: of which: United Kingdom | B31: 287.6 | C31: 271.4
A32: Source: Clarkson PLC 2025 Annual Report, Note 4 "Segmental information" — Geographical segments by origin of invoice.

Sheet Calculations
A1: Clarkson PLC (LSE: CKN) — Segment Calculations
A3: 1. Revenue Mix — Segment Revenue ÷ Total Segment Revenue (%)
A4: Segment | B4: FY2024 | C4: FY2025 | D4: H1 2025 | E4: H1 2026
A5: Broking | B5: =Data!B5/Data!B9 -> 0.80027215 | C5: =Data!C5/Data!C9 -> 0.75388027 | D5: =Data!D5/Data!D9 -> 0.74613835 | E5: =Data!E5/Data!E9 -> 0.75042322
A6: Financial | B6: =Data!B6/Data!B9 -> 0.06440883 | C6: =Data!C6/Data!C9 -> 0.095185303 | D6: =Data!D6/Data!D9 -> 0.097044997 | E6: =Data!E6/Data!E9 -> 0.11632406
A7: Support | B7: =Data!B7/Data!B9 -> 0.098276383 | C7: =Data!C7/Data!C9 -> 0.10785556 | D7: =Data!D7/Data!D9 -> 0.1128274 | E7: =Data!E7/Data!E9 -> 0.096735187
A8: Research | B8: =Data!B8/Data!B9 -> 0.037042637 | C8: =Data!C8/Data!C9 -> 0.043078872 | D8: =Data!D8/Data!D9 -> 0.043989255 | E8: =Data!E8/Data!E9 -> 0.036517533
A9: Total | B9: =SUM(B5:B8) -> 1 | C9: =SUM(C5:C8) -> 1 | D9: =SUM(D5:D8) -> 1 | E9: =SUM(E5:E8) -> 1
A12: 2. Operating Profit Mix — Segment Op. Profit ÷ Total Segment Op. Profit (%)
A13: Segment | B13: FY2024 | C13: FY2025 | D13: H1 2025 | E13: H1 2026
A14: Broking | B14: =Data!F5/Data!F9 -> 0.84551724 | C14: =Data!G5/Data!G9 -> 0.76841244 | D14: =Data!H5/Data!H9 -> 0.76979742 | E14: =Data!I5/Data!I9 -> 0.7587822
A15: Financial | B15: =Data!F6/Data!F9 -> 0.035862069 | C15: =Data!G6/Data!G9 -> 0.10556465 | D15: =Data!H6/Data!H9 -> 0.082872928 | E15: =Data!I6/Data!I9 -> 0.13700234
A16: Support | B16: =Data!F7/Data!F9 -> 0.053103448 | C16: =Data!G7/Data!G9 -> 0.039279869 | D16: =Data!H7/Data!H9 -> 0.053406998 | E16: =Data!I7/Data!I9 -> 0.030444965
A17: Research | B17: =Data!F8/Data!F9 -> 0.065517241 | C17: =Data!G8/Data!G9 -> 0.086743044 | D17: =Data!H8/Data!H9 -> 0.093922652 | E17: =Data!I8/Data!I9 -> 0.073770492
A18: Total | B18: =SUM(B14:B17) -> 1 | C18: =SUM(C14:C17) -> 1 | D18: =SUM(D14:D17) -> 1 | E18: =SUM(E14:E17) -> 1
A21: 3. Operating Margin — Segment Op. Profit ÷ Segment Revenue (%)
A22: Segment | B22: FY2024 | C22: FY2025 | D22: H1 2025 | E22: H1 2026
A23: Broking | B23: =Data!F5/Data!B5 -> 0.23162668 | C23: =Data!G5/Data!C5 -> 0.19726891 | D23: =Data!H5/Data!D5 -> 0.18811881 | E23: =Data!I5/Data!E5 -> 0.20883016
A24: Financial | B24: =Data!F6/Data!B6 -> 0.12206573 | C24: =Data!G6/Data!C6 -> 0.21464226 | D24: =Data!H6/Data!D6 -> 0.15570934 | E24: =Data!I6/Data!E6 -> 0.24324324
A25: Support | B25: =Data!F7/Data!B7 -> 0.11846154 | C25: =Data!G7/Data!C7 -> 0.070484581 | D25: =Data!H7/Data!D7 -> 0.086309524 | E25: =Data!I7/Data!E7 -> 0.065
A26: Research | B26: =Data!F8/Data!B8 -> 0.3877551 | C26: =Data!G8/Data!C8 -> 0.38970588 | D26: =Data!H8/Data!D8 -> 0.38931298 | E26: =Data!I8/Data!E8 -> 0.41721854
A29: 4. Head Office Cost Erosion — |Head Office Costs| ÷ Total Segment Op. Profit (%)
A30: Segment | B30: FY2024 | C30: FY2025 | D30: H1 2025 | E30: H1 2026
A31: Group | B31: =ABS(Data!F10)/Data!F9 -> 0.29862069 | C31: =ABS(Data!G10)/Data!G9 -> 0.36170213 | D31: =ABS(Data!H10)/Data!H9 -> 0.39779006 | E31: =ABS(Data!I10)/Data!I9 -> 0.33489461
A34: 5. Revenue per Employee — Segment Revenue (£m) × 1000 ÷ Avg. Employees (£'000)
A35: Segment | B35: FY2024 | C35: FY2025
A36: Broking | B36: =Data!B5*1000/Data!B17 -> 377.5321 | C36: =Data!C5*1000/Data!C17 -> 316.48936
A37: Financial | B37: =Data!B6*1000/Data!B18 -> 357.98319 | C37: =Data!C6*1000/Data!C18 -> 473.22835
A38: Support | B38: =Data!B7*1000/Data!B19 -> 150.46296 | C38: =Data!C7*1000/Data!C19 -> 149.01532
A39: Research | B39: =Data!B8*1000/Data!B20 -> 163.33333 | C39: =Data!C8*1000/Data!C20 -> 162.87425
A40: Group Average | B40: =Data!B9*1000/Data!B21 -> 314.50309 | C40: =Data!C9*1000/Data!C21 -> 280
A43: 6. Operating Profit per Employee — Segment Op. Profit (£m) × 1000 ÷ Avg. Employees (£'000)
A44: Segment | B44: FY2024 | C44: FY2025
A45: Broking | B45: =Data!F5*1000/Data!B17 -> 87.446505 | C45: =Data!G5*1000/Data!C17 -> 62.433511
A46: Financial | B46: =Data!F6*1000/Data!B18 -> 43.697479 | C46: =Data!G6*1000/Data!C18 -> 101.5748
A47: Support | B47: =Data!F7*1000/Data!B19 -> 17.824074 | C47: =Data!G7*1000/Data!C19 -> 10.503282
A48: Research | B48: =Data!F8*1000/Data!B20 -> 63.333333 | C48: =Data!G8*1000/Data!C20 -> 63.473054
A49: Group Average | B49: =Data!F9*1000/Data!B21 -> 68.94912 | C49: =Data!G9*1000/Data!C21 -> 54.190687
A52: 7. Geographic Revenue Mix — Region Revenue ÷ Total Revenue (%)
A53: Segment | B53: FY2024 | C53: FY2025
...
