Workbook

Sheet README_Sources
A1: FX_Data.xlsx — README & source catalog (Step 1: raw data only, no analysis)
A2: As-of date: 2026-10-07 | Retrieval date: 2026-10-07 | Blue font = raw value from source; black = formula.
A3: Scope: USD, KRW, NOK, GBP, EUR (France + Germany share EUR), CNY; BRL and JPY only as reference for one test. History: FX daily 2016-01-01→latest; rates & CPI monthly 2016→latest; annual macro 2010→latest + IMF forecasts 2026-2028. Quote direction is always written as "X per Y" (= units of X for 1 Y).
A5: Sheet | B5: Column / block | C5: Provider | D5: Series ID / table | E5: Description | F5: URL | G5: Unit | H5: Frequency | I5: First obs | J5: Last obs | K5: Retrieval date | L5: Notes
A6: FX_Daily | B6: B (KRW per USD) | C6: FRED (St. Louis Fed); original source Federal Reserve Board H.10 | D6: DEXKOUS | E6: South Korean Won to U.S. Dollar Spot Exchange Rate (DEXKOUS) | F6: https://fred.stlouisfed.org/series/DEXKOUS | G6: South Korean Won to One U.S. Dollar | H6: Daily | I6: =FX_Daily!B10 -> 42373 | J6: =FX_Daily!B11 -> 46297 | K6: 2026-10-07
A7: FX_Daily | B7: C (NOK per USD) | C7: FRED (St. Louis Fed); original source Federal Reserve Board H.10 | D7: DEXNOUS | E7: Norwegian Kroner to U.S. Dollar Spot Exchange Rate (DEXNOUS) | F7: https://fred.stlouisfed.org/series/DEXNOUS | G7: Norwegian Kroner to One U.S. Dollar | H7: Daily | I7: =FX_Daily!C10 -> 42373 | J7: =FX_Daily!C11 -> 46297 | K7: 2026-10-07
A8: FX_Daily | B8: D (USD per GBP) | C8: FRED (St. Louis Fed); original source Federal Reserve Board H.10 | D8: DEXUSUK | E8: U.S. Dollars to U.K. Pound Sterling Spot Exchange Rate (DEXUSUK) | F8: https://fred.stlouisfed.org/series/DEXUSUK | G8: U.S. Dollars to One U.K. Pound Sterling | H8: Daily | I8: =FX_Daily!D10 -> 42373 | J8: =FX_Daily!D11 -> 46297 | K8: 2026-10-07
A9: FX_Daily | B9: E (USD per EUR) | C9: FRED (St. Louis Fed); original source Federal Reserve Board H.10 | D9: DEXUSEU | E9: U.S. Dollars to Euro Spot Exchange Rate (DEXUSEU) | F9: https://fred.stlouisfed.org/series/DEXUSEU | G9: U.S. Dollars to One Euro | H9: Daily | I9: =FX_Daily!E10 -> 42373 | J9: =FX_Daily!E11 -> 46297 | K9: 2026-10-07
A10: FX_Daily | B10: F (CNY per USD) | C10: FRED (St. Louis Fed); original source Federal Reserve Board H.10 | D10: DEXCHUS | E10: Chinese Yuan Renminbi to U.S. Dollar Spot Exchange Rate (DEXCHUS) | F10: https://fred.stlouisfed.org/series/DEXCHUS | G10: Chinese Yuan Renminbi to One U.S. Dollar | H10: Daily | I10: =FX_Daily!F10 -> 42373 | J10: =FX_Daily!F11 -> 46297 | K10: 2026-10-07
A11: FX_Daily | B11: G (BRL per USD (reference only)) | C11: FRED (St. Louis Fed); original source Federal Reserve Board H.10 | D11: DEXBZUS | E11: Brazilian Reals to U.S. Dollar Spot Exchange Rate (DEXBZUS) | F11: https://fred.stlouisfed.org/series/DEXBZUS | G11: Brazilian Reals to One U.S. Dollar | H11: Daily | I11: =FX_Daily!G10 -> 42373 | J11: =FX_Daily!G11 -> 46297 | K11: 2026-10-07
A12: FX_Daily | B12: H (JPY per USD (reference only)) | C12: FRED (St. Louis Fed); original source Federal Reserve Board H.10 | D12: DEXJPUS | E12: Japanese Yen to U.S. Dollar Spot Exchange Rate (DEXJPUS) | F12: https://fred.stlouisfed.org/series/DEXJPUS | G12: Japanese Yen to One U.S. Dollar | H12: Daily | I12: =FX_Daily!H10 -> 42373 | J12: =FX_Daily!H11 -> 46297 | K12: 2026-10-07
A13: FX_Daily | B13: I (USD per EUR (ECB ref.)) | C13: European Central Bank (ECB Data Portal) | D13: EXR.D.USD.EUR.SP00.A | E13: US dollar/Euro ECB reference exchange rate — USD per 1 EUR | F13: https://data.ecb.europa.eu/data/datasets/EXR/EXR.D.USD.EUR.SP00.A | G13: USD per 1 EUR | H13: Daily (TARGET days, 14:15 CET) | I13: =FX_Daily!I10 -> 42373 | J13: =FX_Daily!I11 -> 46301 | K13: 2026-10-07
A14: FX_Daily | B14: J (NOK per EUR (ECB ref.)) | C14: European Central Bank (ECB Data Portal) | D14: EXR.D.NOK.EUR.SP00.A | E14: Norwegian krone/Euro ECB reference exchange rate — NOK per 1 EUR | F14: https://data.ecb.europa.eu/data/datasets/EXR/EXR.D.NOK.EUR.SP00.A | G14: NOK per 1 EUR | H14: Daily (TARGET days, 14:15 CET) | I14: =FX_Daily!J10 -> 42373 | J14: =FX_Daily!J11 -> 46301 | K14: 2026-10-07
A15: FX_Daily | B15: K (KRW per EUR (ECB ref.)) | C15: European Central Bank (ECB Data Portal) | D15: EXR.D.KRW.EUR.SP00.A | E15: South Korean won/Euro ECB reference exchange rate — KRW per 1 EUR | F15: https://data.ecb.europa.eu/data/datasets/EXR/EXR.D.KRW.EUR.SP00.A | G15: KRW per 1 EUR | H15: Daily (TARGET days, 14:15 CET) | I15: =FX_Daily!K10 -> 42373 | J15: =FX_Daily!K11 -> 46301 | K15: 2026-10-07
A16: FX_Daily | B16: L (GBP per EUR (ECB ref.)) | C16: European Central Bank (ECB Data Portal) | D16: EXR.D.GBP.EUR.SP00.A | E16: Pound sterling/Euro ECB reference exchange rate — GBP per 1 EUR | F16: https://data.ecb.europa.eu/data/datasets/EXR/EXR.D.GBP.EUR.SP00.A | G16: GBP per 1 EUR | H16: Daily (TARGET days, 14:15 CET) | I16: =FX_Daily!L10 -> 42373 | J16: =FX_Daily!L11 -> 46301 | K16: 2026-10-07
A17: FX_Daily | B17: M (CNY per EUR (ECB ref.)) | C17: European Central Bank (ECB Data Portal) | D17: EXR.D.CNY.EUR.SP00.A | E17: Chinese yuan renminbi/Euro ECB reference exchange rate — CNY per 1 EUR | F17: https://data.ecb.europa.eu/data/datasets/EXR/EXR.D.CNY.EUR.SP00.A | G17: CNY per 1 EUR | H17: Daily (TARGET days, 14:15 CET) | I17: =FX_Daily!M10 -> 42373 | J17: =FX_Daily!M11 -> 46301 | K17: 2026-10-07
A18: FX_Daily | B18: N (BRL per EUR (ECB ref.)) | C18: European Central Bank (ECB Data Portal) | D18: EXR.D.BRL.EUR.SP00.A | E18: Brazilian real/Euro ECB reference exchange rate — BRL per 1 EUR | F18: https://data.ecb.europa.eu/data/datasets/EXR/EXR.D.BRL.EUR.SP00.A | G18: BRL per 1 EUR | H18: Daily (TARGET days, 14:15 CET) | I18: =FX_Daily!N10 -> 42373 | J18: =FX_Daily!N11 -> 46301 | K18: 2026-10-07
A19: FX_Daily | B19: O (JPY per EUR (ECB ref.)) | C19: European Central Bank (ECB Data Portal) | D19: EXR.D.JPY.EUR.SP00.A | E19: Japanese yen/Euro ECB reference exchange rate — JPY per 1 EUR | F19: https://data.ecb.europa.eu/data/datasets/EXR/EXR.D.JPY.EUR.SP00.A | G19: JPY per 1 EUR | H19: Daily (TARGET days, 14:15 CET) | I19: =FX_Daily!O10 -> 42373 | J19: =FX_Daily!O11 -> 46301 | K19: 2026-10-07
A20: FX_Daily | B20: P (NOK per USD (Norges Bank)) | C20: Norges Bank (data.norges-bank.no) | D20: EXR/B.USD.NOK.SP | E20: Norges Bank daily exchange rate, NOK per 1 USD (midday fixing) | F20: https://data.norges-bank.no/api/data/EXR/B.USD.NOK.SP?format=csv | G20: NOK per 1 USD | H20: Daily (Norwegian business days) | I20: =FX_Daily!P10 -> 42373 | J20: =FX_Daily!P11 -> 46301 | K20: 2026-10-07
A21: FX_Monthly | B21: B:P | C21: Derived (formula) | D21: AVERAGEIFS on FX_Daily | E21: Monthly average of every FX_Daily series; same quote direction as FX_Daily | G21: as FX_Daily | H21: Monthly | I21: =FX_Monthly!B10 -> 42370 | J21: =FX_Monthly!B11 -> 46296 | K21: 2026-10-07 | L21: Derived, not a separate source series. Current month flagged "partial month".
A22: Rates_Daily | B22: B (USD SOFR (O/N)) | C22: FRED (St. Louis Fed) | D22: SOFR | E22: Secured Overnight Financing Rate (SOFR) | F22: https://fred.stlouisfed.org/series/SOFR | G22: Percent | H22: Daily | I22: =Rates_Daily!B10 -> 43193 | J22: =Rates_Daily!B11 -> 46300 | K22: 2026-10-07
A23: Rates_Daily | B23: C (USD Fed funds target — upper) | C23: FRED (St. Louis Fed) | D23: DFEDTARU | E23: Federal Funds Target Range - Upper Limit (DFEDTARU) | F23: https://fred.stlouisfed.org/series/DFEDTARU | G23: Percent | H23: Daily | I23: =Rates_Daily!C10 -> 42370 | J23: =Rates_Daily!C11 -> 46301 | K23: 2026-10-07
A24: Rates_Daily | B24: D (USD Fed funds target — lower) | C24: FRED (St. Louis Fed) | D24: DFEDTARL | E24: Federal Funds Target Range - Lower Limit (DFEDTARL) | F24: https://fred.stlouisfed.org/series/DFEDTARL | G24: Percent | H24: Daily | I24: =Rates_Daily!D10 -> 42370 | J24: =Rates_Daily!D11 -> 46301 | K24: 2026-10-07
A25: Rates_Daily | B25: E (EUR €STR (O/N)) | C25: European Central Bank (ECB Data Portal) | D25: EST.B.EU000A2X2A25.WT | E25: Euro short-term rate | F25: https://data.ecb.europa.eu/data/datasets/EST/EST.B.EU000A2X2A25.WT | G25: % p.a. | H25: Daily (TARGET days) | I25: =Rates_Daily!E10 -> 43739 | J25: =Rates_Daily!E11 -> 46301 | K25: 2026-10-07
A26: Rates_Daily | B26: F (EUR ECB deposit facility rate) | C26: European Central Bank (ECB Data Portal) | D26: FM.D.U2.EUR.4F.KR.DFR.LEV | E26: Deposit facility - date of changes (raw data) - Level | F26: https://data.ecb.europa.eu/data/datasets/FM/FM.D.U2.EUR.4F.KR.DFR.LEV | G26: % p.a. | H26: Daily (calendar) | I26: =Rates_Daily!F10 -> 42370 | J26: =Rates_Daily!F11 -> 46302 | K26: 2026-10-07
A27: Rates_Daily | B27: G (GBP Bank Rate) | C27: Bank of England (IADB) | D27: IUDBEDR | E27: Official Bank Rate, daily | F27: https://www.bankofengland.co.uk/boeapps/database/?SeriesCodes=IUDBEDR | G27: % p.a. | H27: Daily | I27: =Rates_Daily!G10 -> 42373 | J27: =Rates_Daily!G11 -> 46301 | K27: 2026-10-07
A28: Rates_Daily | B28: H (GBP SONIA (O/N)) | C28: Bank of England (IADB) | D28: IUDSOIA | E28: Sterling Overnight Index Average, daily | F28: https://www.bankofengland.co.uk/boeapps/database/?SeriesCodes=IUDSOIA | G28: % p.a. | H28: Daily | I28: =Rates_Daily!H10 -> 42373 | J28: =Rates_Daily!H11 -> 46300 | K28: 2026-10-07
A29: Rates_Daily | B29: I (GBP OIS spot 1M) | C29: Bank of England (yield curve data) | D29: UK OIS spot curve, 1M maturity | E29: BoE estimated UK OIS (SONIA) spot rate, 1M maturity, continuously compounded per BoE methodology | F29: https://www.bankofengland.co.uk/statistics/yield-curves (files: oisddata.zip, latest-yield-curve-data.zip; sheet "3. spot, short end") | G29: % p.a. | H29: Daily | I29: =Rates_Daily!I10 -> 42373 | J29: =Rates_Daily!I11 -> 46300 | K29: 2026-10-07
A30: Rates_Daily | B30: J (GBP OIS spot 3M) | C30: Bank of England (yield curve data) | D30: UK OIS spot curve, 3M maturity | E30: BoE estimated UK OIS (SONIA) spot rate, 3M maturity, continuously compounded per BoE methodology | F30: https://www.bankofengland.co.uk/statistics/yield-curves (files: oisddata.zip, latest-yield-curve-data.zip; sheet "3. spot, short end") | G30: % p.a. | H30: Daily | I30: =Rates_Daily!J10 -> 42373 | J30: =Rates_Daily!J11 -> 46300 | K30: 2026-10-07
A31: Rates_Daily | B31: K (GBP OIS spot 6M) | C31: Bank of England (yield curve data) | D31: UK OIS spot curve, 6M maturity | E31: BoE estimated UK OIS (SONIA) spot rate, 6M maturity, continuously compounded per BoE methodology | F31: https://www.bankofengland.co.uk/statistics/yield-curves (files: oisddata.zip, latest-yield-curve-data.zip; sheet "3. spot, short end") | G31: % p.a. | H31: Daily | I31: =Rates_Daily!K10 -> 42373 | J31: =Rates_Daily!K11 -> 46300 | K31: 2026-10-07
A32: Rates_Daily | B32: L (GBP OIS spot 12M) | C32: Bank of England (yield curve data) | D32: UK OIS spot curve, 12M maturity | E32: BoE estimated UK OIS (SONIA) spot rate, 12M maturity, continuously compounded per BoE methodology | F32: https://www.bankofengland.co.uk/statistics/yield-curves (files: oisddata.zip, latest-yield-curve-data.zip; sheet "3. spot, short end") | G32: % p.a. | H32: Daily | I32: =Rates_Daily!L10 -> 42373 | J32: =Rates_Daily!L11 -> 46300 | K32: 2026-10-07
A33: Rates_Daily | B33: M (CNY Shibor 1M) | C33: CFETS / National Interbank Funding Center (chinamoney.com.cn) | D33: Shibor 1M | E33: Shanghai Interbank Offered Rate, 1M tenor | F33: https://www.chinamoney.com.cn/english/bmkshibor/ (API: /ags/ms/cm-u-bk-shibor/ShiborHis) | G33: % p.a. | H33: Daily (China business days) | I33: =Rates_Daily!M10 -> 42373 | J33: =Rates_Daily!M11 -> 46295 | K33: 2026-10-07
A34: Rates_Daily | B34: N (CNY Shibor 3M) | C34: CFETS / National Interbank Funding Center (chinamoney.com.cn) | D34: Shibor 3M | E34: Shanghai Interbank Offered Rate, 3M tenor | F34: https://www.chinamoney.com.cn/english/bmkshibor/ (API: /ags/ms/cm-u-bk-shibor/ShiborHis) | G34: % p.a. | H34: Daily (China business days) | I34: =Rates_Daily!N10 -> 42373 | J34: =Rates_Daily!N11 -> 46295 | K34: 2026-10-07
A35: Rates_Daily | B35: O (CNY Shibor 6M) | C35: CFETS / National Interbank Funding Center (chinamoney.com.cn) | D35: Shibor 6M | E35: Shanghai Interbank Offered Rate, 6M tenor | F35: https://www.chinamoney.com.cn/english/bmkshibor/ (API: /ags/ms/cm-u-bk-shibor/ShiborHis) | G35: % p.a. | H35: Daily (China business days) | I35: =Rates_Daily!O10 -> 42373 | J35: =Rates_Daily!O11 -> 46295 | K35: 2026-10-07
A36: Rates_Daily | B36: P (CNY Shibor 1Y) | C36: CFETS / National Interbank Funding Center (chinamoney.com.cn) | D36: Shibor 1Y | E36: Shanghai Interbank Offered Rate, 1Y tenor | F36: https://www.chinamoney.com.cn/english/bmkshibor/ (API: /ags/ms/cm-u-bk-shibor/ShiborHis) | G36: % p.a. | H36: Daily (China business days) | I36: =Rates_Daily!P10 -> 42373 | J36: =Rates_Daily!P11 -> 46295 | K36: 2026-10-07
A37: Rates_Daily | B37: Q (NOK Norges Bank policy rate) | C37: Norges Bank | D37: IR/B.KPRA.SD. | E37: Key policy rate (sight deposit rate), daily | F37: https://data.norges-bank.no/api/data/IR/B.KPRA.SD.?format=csv | G37: % p.a. | H37: Daily | I37: =Rates_Daily!Q10 -> 42373 | J37: =Rates_Daily!Q11 -> 46301 | K37: 2026-10-07
A38: Rates_Daily | B38: R (NOK NOWA (O/N)) | C38: Norges Bank | D38: SHORT_RATES/B.NOWA.ON.R | E38: Norwegian Overnight Weighted Average, daily | F38: https://data.norges-bank.no/api/data/SHORT_RATES/B.NOWA.ON.R?format=csv | G38: % p.a. | H38: Daily | I38: =Rates_Daily!R10 -> 42373 | J38: =Rates_Daily!R11 -> 46301 | K38: 2026-10-07
A39: Rates_Daily | B39: S (BRL Selic target (reference only)) | C39: Banco Central do Brasil (SGS) | D39: SGS 432 | E39: Meta Selic definida pelo Copom (% a.a.) | F39: https://api.bcb.gov.br/dados/serie/bcdata.sgs.432/dados?formato=json | G39: % p.a. | H39: Daily | I39: =Rates_Daily!S10 -> 42370 | J39: =Rates_Daily!S11 -> 46302 | K39: 2026-10-07
A40: Rates_Monthly | B40: B (USD Fed funds effective) | C40: FRED (St. Louis Fed) | D40: FEDFUNDS | E40: Federal Funds Effective Rate (FEDFUNDS) | F40: https://fred.stlouisfed.org/series/FEDFUNDS | G40: Percent | H40: Monthly | I40: =Rates_Monthly!B10 -> 42370 | J40: =Rates_Monthly!B11 -> 46266 | K40: 2026-10-07
A41: Rates_Monthly | B41: C (USD Fed target upper (month-end)) | C41: FRED (St. Louis Fed) | D41: DFEDTARU → Month-end value (last daily obs <= month end; formula on Rates_Daily) | E41: Federal Funds Target Range - Upper Limit (DFEDTARU) | F41: https://fred.stlouisfed.org/series/DFEDTARU | G41: Percent | H41: Month-end value (last daily obs <= month end; formula on Rates_Daily) | I41: =Rates_Monthly!C10 -> 42370 | J41: =Rates_Monthly!C11 -> 46296 | K41: 2026-10-07
...

Sheet FX_Daily
A1: FX_Daily — daily spot exchange rates (raw)
A2: As-of date: 2026-10-07 | Retrieval date: 2026-10-07 | Blue font = raw value from source; black = formula. Blank cell = no fixing published by that source on that date (market holiday). Quote direction in each header.
A4: Provider | B4: FRED (St. Louis Fed); original source Federal Reserve Board H.10 | C4: FRED (St. Louis Fed); original source Federal Reserve Board H.10 | D4: FRED (St. Louis Fed); original source Federal Reserve Board H.10 | E4: FRED (St. Louis Fed); original source Federal Reserve Board H.10 | F4: FRED (St. Louis Fed); original source Federal Reserve Board H.10 | G4: FRED (St. Louis Fed); original source Federal Reserve Board H.10 | H4: FRED (St. Louis Fed); original source Federal Reserve Board H.10 | I4: European Central Bank (ECB Data Portal) | J4: European Central Bank (ECB Data Portal) | K4: European Central Bank (ECB Data Portal) | L4: European Central Bank (ECB Data Portal) | M4: European Central Bank (ECB Data Portal) | N4: European Central Bank (ECB Data Portal) | O4: European Central Bank (ECB Data Portal) | P4: Norges Bank (data.norges-bank.no)
A5: Series ID / table | B5: DEXKOUS | C5: DEXNOUS | D5: DEXUSUK | E5: DEXUSEU | F5: DEXCHUS | G5: DEXBZUS | H5: DEXJPUS | I5: EXR.D.USD.EUR.SP00.A | J5: EXR.D.NOK.EUR.SP00.A | K5: EXR.D.KRW.EUR.SP00.A | L5: EXR.D.GBP.EUR.SP00.A | M5: EXR.D.CNY.EUR.SP00.A | N5: EXR.D.BRL.EUR.SP00.A | O5: EXR.D.JPY.EUR.SP00.A | P5: EXR/B.USD.NOK.SP
A6: Description (quote direction) | B6: South Korean Won to U.S. Dollar Spot Exchange Rate (DEXKOUS) | C6: Norwegian Kroner to U.S. Dollar Spot Exchange Rate (DEXNOUS) | D6: U.S. Dollars to U.K. Pound Sterling Spot Exchange Rate (DEXUSUK) | E6: U.S. Dollars to Euro Spot Exchange Rate (DEXUSEU) | F6: Chinese Yuan Renminbi to U.S. Dollar Spot Exchange Rate (DEXCHUS) | G6: Brazilian Reals to U.S. Dollar Spot Exchange Rate (DEXBZUS) | H6: Japanese Yen to U.S. Dollar Spot Exchange Rate (DEXJPUS) | I6: US dollar/Euro ECB reference exchange rate — USD per 1 EUR | J6: Norwegian krone/Euro ECB reference exchange rate — NOK per 1 EUR | K6: South Korean won/Euro ECB reference exchange rate — KRW per 1 EUR | L6: Pound sterling/Euro ECB reference exchange rate — GBP per 1 EUR | M6: Chinese yuan renminbi/Euro ECB reference exchange rate — CNY per 1 EUR | N6: Brazilian real/Euro ECB reference exchange rate — BRL per 1 EUR | O6: Japanese yen/Euro ECB reference exchange rate — JPY per 1 EUR | P6: Norges Bank daily exchange rate, NOK per 1 USD (midday fixing)
A7: Unit | B7: South Korean Won to One U.S. Dollar | C7: Norwegian Kroner to One U.S. Dollar | D7: U.S. Dollars to One U.K. Pound Sterling | E7: U.S. Dollars to One Euro | F7: Chinese Yuan Renminbi to One U.S. Dollar | G7: Brazilian Reals to One U.S. Dollar | H7: Japanese Yen to One U.S. Dollar | I7: USD per 1 EUR | J7: NOK per 1 EUR | K7: KRW per 1 EUR | L7: GBP per 1 EUR | M7: CNY per 1 EUR | N7: BRL per 1 EUR | O7: JPY per 1 EUR | P7: NOK per 1 USD
A8: Frequency | B8: Daily | C8: Daily | D8: Daily | E8: Daily | F8: Daily | G8: Daily | H8: Daily | I8: Daily (TARGET days, 14:15 CET) | J8: Daily (TARGET days, 14:15 CET) | K8: Daily (TARGET days, 14:15 CET) | L8: Daily (TARGET days, 14:15 CET) | M8: Daily (TARGET days, 14:15 CET) | N8: Daily (TARGET days, 14:15 CET) | O8: Daily (TARGET days, 14:15 CET) | P8: Daily (Norwegian business days)
A9: URL | B9: https://fred.stlouisfed.org/series/DEXKOUS | C9: https://fred.stlouisfed.org/series/DEXNOUS | D9: https://fred.stlouisfed.org/series/DEXUSUK | E9: https://fred.stlouisfed.org/series/DEXUSEU | F9: https://fred.stlouisfed.org/series/DEXCHUS | G9: https://fred.stlouisfed.org/series/DEXBZUS | H9: https://fred.stlouisfed.org/series/DEXJPUS | I9: https://data.ecb.europa.eu/data/datasets/EXR/EXR.D.USD.EUR.SP00.A | J9: https://data.ecb.europa.eu/data/datasets/EXR/EXR.D.NOK.EUR.SP00.A | K9: https://data.ecb.europa.eu/data/datasets/EXR/EXR.D.KRW.EUR.SP00.A | L9: https://data.ecb.europa.eu/data/datasets/EXR/EXR.D.GBP.EUR.SP00.A | M9: https://data.ecb.europa.eu/data/datasets/EXR/EXR.D.CNY.EUR.SP00.A | N9: https://data.ecb.europa.eu/data/datasets/EXR/EXR.D.BRL.EUR.SP00.A | O9: https://data.ecb.europa.eu/data/datasets/EXR/EXR.D.JPY.EUR.SP00.A | P9: https://data.norges-bank.no/api/data/EXR/B.USD.NOK.SP?format=csv
A10: First observation (formula) | B10: =IFERROR(_xlfn.MINIFS($A$15:$A$2821,B$15:B$2821,">=-1E+99"),"N/A") -> 42373 | C10: =IFERROR(_xlfn.MINIFS($A$15:$A$2821,C$15:C$2821,">=-1E+99"),"N/A") -> 42373 | D10: =IFERROR(_xlfn.MINIFS($A$15:$A$2821,D$15:D$2821,">=-1E+99"),"N/A") -> 42373 | E10: =IFERROR(_xlfn.MINIFS($A$15:$A$2821,E$15:E$2821,">=-1E+99"),"N/A") -> 42373 | F10: =IFERROR(_xlfn.MINIFS($A$15:$A$2821,F$15:F$2821,">=-1E+99"),"N/A") -> 42373 | G10: =IFERROR(_xlfn.MINIFS($A$15:$A$2821,G$15:G$2821,">=-1E+99"),"N/A") -> 42373 | H10: =IFERROR(_xlfn.MINIFS($A$15:$A$2821,H$15:H$2821,">=-1E+99"),"N/A") -> 42373 | I10: =IFERROR(_xlfn.MINIFS($A$15:$A$2821,I$15:I$2821,">=-1E+99"),"N/A") -> 42373 | ... P10: =IFERROR(_xlfn.MINIFS($A$15:$A$2821,P$15:P$2821,">=-1E+99"),"N/A") -> 42373
A11: Last observation (formula) | B11: =IFERROR(_xlfn.MAXIFS($A$15:$A$2821,B$15:B$2821,">=-1E+99"),"N/A") -> 46297 | C11: =IFERROR(_xlfn.MAXIFS($A$15:$A$2821,C$15:C$2821,">=-1E+99"),"N/A") -> 46297 | D11: =IFERROR(_xlfn.MAXIFS($A$15:$A$2821,D$15:D$2821,">=-1E+99"),"N/A") -> 46297 | E11: =IFERROR(_xlfn.MAXIFS($A$15:$A$2821,E$15:E$2821,">=-1E+99"),"N/A") -> 46297 | F11: =IFERROR(_xlfn.MAXIFS($A$15:$A$2821,F$15:F$2821,">=-1E+99"),"N/A") -> 46297 | G11: =IFERROR(_xlfn.MAXIFS($A$15:$A$2821,G$15:G$2821,">=-1E+99"),"N/A") -> 46297 | H11: =IFERROR(_xlfn.MAXIFS($A$15:$A$2821,H$15:H$2821,">=-1E+99"),"N/A") -> 46297 | I11: =IFERROR(_xlfn.MAXIFS($A$15:$A$2821,I$15:I$2821,">=-1E+99"),"N/A") -> 46301 | ... P11: =IFERROR(_xlfn.MAXIFS($A$15:$A$2821,P$15:P$2821,">=-1E+99"),"N/A") -> 46301
A12: Last value (formula) | B12: =IFERROR(INDEX(B$15:B$2821,MATCH(B11,$A$15:$A$2821,0)),"N/A") -> 1345.75 | C12: =IFERROR(INDEX(C$15:C$2821,MATCH(C11,$A$15:$A$2821,0)),"N/A") -> 9.6386 | D12: =IFERROR(INDEX(D$15:D$2821,MATCH(D11,$A$15:$A$2821,0)),"N/A") -> 1.3234 | E12: =IFERROR(INDEX(E$15:E$2821,MATCH(E11,$A$15:$A$2821,0)),"N/A") -> 1.1259 | F12: =IFERROR(INDEX(F$15:F$2821,MATCH(F11,$A$15:$A$2821,0)),"N/A") -> 6.7038 | G12: =IFERROR(INDEX(G$15:G$2821,MATCH(G11,$A$15:$A$2821,0)),"N/A") -> 5.2222 | H12: =IFERROR(INDEX(H$15:H$2821,MATCH(H11,$A$15:$A$2821,0)),"N/A") -> 157.81 | I12: =IFERROR(INDEX(I$15:I$2821,MATCH(I11,$A$15:$A$2821,0)),"N/A") -> 1.1269 | ... P12: =IFERROR(INDEX(P$15:P$2821,MATCH(P11,$A$15:$A$2821,0)),"N/A") -> 9.5643
A13: Observations (count, formula) | B13: =COUNT(B$15:B$2821) -> 2687 | C13: =COUNT(C$15:C$2821) -> 2687 | D13: =COUNT(D$15:D$2821) -> 2687 | E13: =COUNT(E$15:E$2821) -> 2687 | F13: =COUNT(F$15:F$2821) -> 2687 | G13: =COUNT(G$15:G$2821) -> 2687 | H13: =COUNT(H$15:H$2821) -> 2687 | I13: =COUNT(I$15:I$2821) -> 2755 | ... P13: =COUNT(P$15:P$2821) -> 2708
A14: Date | B14: KRW per USD | C14: NOK per USD | D14: USD per GBP | E14: USD per EUR | F14: CNY per USD | G14: BRL per USD (reference only) | H14: JPY per USD (reference only) | I14: USD per EUR (ECB ref.) | J14: NOK per EUR (ECB ref.) | K14: KRW per EUR (ECB ref.) | L14: GBP per EUR (ECB ref.) | M14: CNY per EUR (ECB ref.) | N14: BRL per EUR (ECB ref.) | O14: JPY per EUR (ECB ref.) | P14: NOK per USD (Norges Bank)
A15: 42373 | B15: 1191.46 | C15: 8.9246 | D15: 1.4686 | E15: 1.0803 | F15: 6.5338 | G15: 4.0613 | H15: 119.3 | I15: 1.0898 | J15: 9.6475 | K15: 1297.87 | L15: 0.7381 | M15: 7.1208 | N15: 4.4023 | O15: 129.78 | P15: 8.8525
A16: 42374 | B16: 1190.43 | C16: 8.9165 | D16: 1.4664 | E16: 1.0743 | F16: 6.5219 | G16: 4.0108 | H16: 118.95 | I16: 1.0746 | J16: 9.588 | K16: 1277.02 | L16: 0.73235 | M16: 7.0074 | N16: 4.3023 | O16: 127.88 | P16: 8.9224
A17: 42375 | B17: 1200.16 | C17: 8.9668 | D17: 1.4626 | E17: 1.0762 | F17: 6.5554 | G17: 4.0163 | H17: 118.54 | I17: 1.0742 | J17: 9.6225 | K17: 1289.2 | L17: 0.7344 | M17: 7.0388 | N17: 4.3331 | O17: 127.19 | P17: 8.9578
A18: 42376 | B18: 1193.05 | C18: 8.919 | D18: 1.4579 | E18: 1.086 | F18: 6.5926 | G18: 4.0504 | H18: 118 | I18: 1.0868 | J18: 9.6975 | K18: 1306.87 | L18: 0.74545 | M18: 7.1672 | N18: 4.4001 | O18: 127.74 | P18: 8.923
A19: 42377 | B19: 1206.97 | C19: 8.9045 | D19: 1.4523 | E19: 1.0885 | F19: 6.5932 | G19: 4.048 | H19: 117.74 | I19: 1.0861 | J19: 9.681 | K19: 1304.78 | L19: 0.74519 | M19: 7.1577 | N19: 4.3685 | O19: 128.51 | P19: 8.9135
A20: 42380 | B20: 1206.55 | C20: 8.9399 | D20: 1.4564 | E20: 1.0878 | F20: 6.5675 | G20: 4.0464 | H20: 117.48 | I20: 1.0888 | J20: 9.677 | K20: 1309.12 | L20: 0.74705 | M20: 7.1554 | N20: 4.3786 | O20: 128.33 | P20: 8.8878
A21: 42381 | B21: 1208.95 | C21: 8.9039 | D21: 1.4403 | E21: 1.0837 | F21: 6.57 | G21: 4.0454 | H21: 117.78 | I21: 1.0836 | J21: 9.6388 | K21: 1308.87 | L21: 0.7508 | M21: 7.1276 | N21: 4.3704 | O21: 127.79 | P21: 8.8952
A22: 42382 | B22: 1208.95 | C22: 8.8019 | D22: 1.447 | E22: 1.0862 | F22: 6.57 | G22: 3.9893 | H22: 118.06 | I22: 1.0816 | J22: 9.5588 | K22: 1301.18 | L22: 0.7502 | M22: 7.1121 | N22: 4.3214 | O22: 127.74 | P22: 8.8376
A23: 42383 | B23: 1211.28 | C23: 8.7635 | D23: 1.4409 | E23: 1.0862 | F23: 6.5891 | G23: 4.0032 | H23: 118.03 | I23: 1.0893 | J23: 9.6071 | K23: 1320.77 | L23: 0.75703 | M23: 7.1809 | N23: 4.373 | O23: 128.26 | P23: 8.8195
A24: 42384 | B24: 1216.95 | C24: 8.8195 | D24: 1.4289 | E24: 1.0964 | F24: 6.584 | G24: 4.048 | H24: 116.78 | I24: 1.0914 | J24: 9.6085 | K24: 1328.97 | L24: 0.7615 | M24: 7.1888 | N24: 4.4139 | O24: 127.8 | P24: 8.8038
A25: 42387 | I25: 1.0892 | J25: 9.6878 | K25: 1317.44 | L25: 0.76263 | M25: 7.1658 | N25: 4.3929 | O25: 127.78 | P25: 8.8944
A26: 42388 | B26: 1205.61 | C26: 8.7946 | D26: 1.4171 | E26: 1.0906 | F26: 6.5783 | G26: 4.042 | H26: 117.66 | I26: 1.0868 | J26: 9.6209 | K26: 1306.89 | L26: 0.76473 | M26: 7.1496 | N26: 4.3758 | O26: 128.12 | P26: 8.8525
A27: 42389 | B27: 1215.4 | C27: 8.898 | D27: 1.4167 | E27: 1.0908 | F27: 6.5781 | G27: 4.1103 | H27: 116.38 | I27: 1.0907 | J27: 9.665 | K27: 1326.46 | L27: 0.77 | M27: 7.1768 | N27: 4.4559 | O27: 127.28 | P27: 8.8613
A28: 42390 | B28: 1204.31 | C28: 8.8153 | D28: 1.4198 | E28: 1.0833 | F28: 6.5794 | G28: 4.1299 | H28: 117.61 | I28: 1.0893 | J28: 9.7033 | K28: 1321.64 | L28: 0.77182 | M28: 7.1666 | N28: 4.523 | O28: 127.43 | P28: 8.9078
A29: 42391 | B29: 1195.66 | C29: 8.759 | D29: 1.4308 | E29: 1.0814 | F29: 6.5788 | G29: 4.1061 | H29: 118.37 | I29: 1.0808 | J29: 9.4685 | K29: 1292.83 | L29: 0.75459 | M29: 7.1104 | N29: 4.455 | O29: 127.77 | P29: 8.7606
A30: 42394 | B30: 1194.3 | C30: 8.7447 | D30: 1.4245 | E30: 1.0832 | F30: 6.579 | G30: 4.0887 | H30: 118.55 | I30: 1.0815 | J30: 9.4585 | K30: 1293.53 | L30: 0.7589 | M30: 7.1156 | N30: 4.4276 | O30: 128.07 | P30: 8.7457
A31: 42395 | B31: 1199.64 | C31: 8.6972 | D31: 1.4342 | E31: 1.0846 | F31: 6.5814 | G31: 4.0701 | H31: 118.5 | I31: 1.0837 | J31: 9.4858 | K31: 1303.82 | L31: 0.76095 | M31: 7.1314 | N31: 4.4465 | O31: 128.22 | P31: 8.7532
A32: 42396 | B32: 1199.25 | C32: 8.6589 | D32: 1.4261 | E32: 1.0867 | F32: 6.5773 | G32: 4.0557 | H32: 118.9 | I32: 1.0888 | J32: 9.4508 | K32: 1308.94 | L32: 0.75965 | M32: 7.1621 | N32: 4.3963 | O32: 128.91 | P32: 8.68
A33: 42397 | B33: 1204.08 | C33: 8.6332 | D33: 1.4351 | E33: 1.0952 | F33: 6.5744 | G33: 4.0979 | H33: 118.61 | I33: 1.0903 | J33: 9.4465 | K33: 1316.36 | L33: 0.76228 | M33: 7.1705 | N33: 4.4753 | O33: 129.62 | P33: 8.6641
A34: 42398 | B34: 1210.04 | C34: 8.7071 | D34: 1.4184 | E34: 1.0832 | F34: 6.5752 | G34: 4.0364 | H34: 121.05 | I34: 1.092 | J34: 9.4845 | K34: 1318.6 | L34: 0.7641 | M34: 7.181 | N34: 4.4294 | O34: 132.25 | P34: 8.6854
A35: 42401 | B35: 1203.19 | C35: 8.7104 | D35: 1.4367 | E35: 1.0888 | F35: 6.5778 | G35: 3.9866 | H35: 121.06 | I35: 1.0884 | J35: 9.416 | K35: 1310.43 | L35: 0.761 | M35: 7.1605 | N35: 4.3511 | O35: 131.99 | P35: 8.6512
A36: 42402 | B36: 1212.01 | C36: 8.7184 | D36: 1.4399 | E36: 1.0908 | F36: 6.5795 | G36: 3.9885 | H36: 120.27 | I36: 1.0919 | J36: 9.5223 | K36: 1322.58 | L36: 0.7586 | M36: 7.1847 | N36: 4.3565 | O36: 131.84 | P36: 8.7209
A37: 42403 | B37: 1211.33 | C37: 8.6074 | D37: 1.4576 | E37: 1.1051 | F37: 6.5765 | G37: 3.9478 | H37: 117.92 | I37: 1.0933 | J37: 9.5138 | K37: 1329.87 | L37: 0.7533 | M37: 7.1916 | N37: 4.328 | O37: 130.58 | P37: 8.7019
... A44: 42412 | B44: 1205.13 | C44: 8.5917 | D44: 1.446 | E44: 1.1235 | F44: 6.571 | G44: 3.9764 | H44: 112.96 | I44: 1.1275 | J44: 9.6773 | K44: 1359.98 | L44: 0.77735 | M44: 7.4114 | N44: 4.5087 | O44: 127.07 | P44: 8.583
A45: 42415 | I45: 1.118 | J45: 9.6313 | K45: 1352.15 | L45: 0.772 | M45: 7.2606 | N45: 4.4567 | O45: 127.6 | P45: 8.6148
A46: 42416 | B46: 1219.44 | C46: 8.6203 | D46: 1.429 | E46: 1.114 | F46: 6.5154 | G46: 4.0564 | H46: 113.9 | I46: 1.1166 | J46: 9.6049 | K46: 1358.7 | L46: 0.7758 | M46: 7.2741 | N46: 4.4833 | O46: 127.02 | P46: 8.6019
A47: 42417 | B47: 1222.32 | C47: 8.5696 | D47: 1.4317 | E47: 1.114 | F47: 6.527 | G47: 3.9856 | H47: 114.14 | I47: 1.1136 | J47: 9.5955 | K47: 1368.24 | L47: 0.77835 | M47: 7.2685 | N47: 4.4866 | O47: 127.1 | P47: 8.6166
...

Sheet FX_Monthly
A1: FX_Monthly — monthly average exchange rates (formulas on FX_Daily)
A2: As-of date: 2026-10-07 | Retrieval date: 2026-10-07 | Blue font = raw value from source; black = formula. All values are AVERAGEIFS formulas over FX_Daily.
A4: Provider | B4: FRED (St. Louis Fed); original source Federal Reserve Board H.10 | C4: FRED (St. Louis Fed); original source Federal Reserve Board H.10 | D4: FRED (St. Louis Fed); original source Federal Reserve Board H.10 | E4: FRED (St. Louis Fed); original source Federal Reserve Board H.10 | F4: FRED (St. Louis Fed); original source Federal Reserve Board H.10 | G4: FRED (St. Louis Fed); original source Federal Reserve Board H.10 | H4: FRED (St. Louis Fed); original source Federal Reserve Board H.10 | I4: European Central Bank (ECB Data Portal) | J4: European Central Bank (ECB Data Portal) | K4: European Central Bank (ECB Data Portal) | L4: European Central Bank (ECB Data Portal) | M4: European Central Bank (ECB Data Portal) | N4: European Central Bank (ECB Data Portal) | O4: European Central Bank (ECB Data Portal) | P4: Norges Bank (data.norges-bank.no) | Q4: Formula | R4: Formula
A5: Series ID / table | B5: DEXKOUS (monthly average computed from FX_Daily) | C5: DEXNOUS (monthly average computed from FX_Daily) | D5: DEXUSUK (monthly average computed from FX_Daily) | E5: DEXUSEU (monthly average computed from FX_Daily) | F5: DEXCHUS (monthly average computed from FX_Daily) | G5: DEXBZUS (monthly average computed from FX_Daily) | H5: DEXJPUS (monthly average computed from FX_Daily) | I5: EXR.D.USD.EUR.SP00.A (monthly average computed from FX_Daily) | J5: EXR.D.NOK.EUR.SP00.A (monthly average computed from FX_Daily) | K5: EXR.D.KRW.EUR.SP00.A (monthly average computed from FX_Daily) | L5: EXR.D.GBP.EUR.SP00.A (monthly average computed from FX_Daily) | M5: EXR.D.CNY.EUR.SP00.A (monthly average computed from FX_Daily) | N5: EXR.D.BRL.EUR.SP00.A (monthly average computed from FX_Daily) | O5: EXR.D.JPY.EUR.SP00.A (monthly average computed from FX_Daily) | P5: EXR/B.USD.NOK.SP (monthly average computed from FX_Daily) | Q5: COUNTIFS on FX_Daily
A6: Description (quote direction) | B6: Arithmetic mean of available daily observations in the calendar month (formula on FX_Daily) | C6: Arithmetic mean of available daily observations in the calendar month (formula on FX_Daily) | D6: Arithmetic mean of available daily observations in the calendar month (formula on FX_Daily) | E6: Arithmetic mean of available daily observations in the calendar month (formula on FX_Daily) | F6: Arithmetic mean of available daily observations in the calendar month (formula on FX_Daily) | G6: Arithmetic mean of available daily observations in the calendar month (formula on FX_Daily) | H6: Arithmetic mean of available daily observations in the calendar month (formula on FX_Daily) | I6: Arithmetic mean of available daily observations in the calendar month (formula on FX_Daily) | J6: Arithmetic mean of available daily observations in the calendar month (formula on FX_Daily) | K6: Arithmetic mean of available daily observations in the calendar month (formula on FX_Daily) | L6: Arithmetic mean of available daily observations in the calendar month (formula on FX_Daily) | M6: Arithmetic mean of available daily observations in the calendar month (formula on FX_Daily) | N6: Arithmetic mean of available daily observations in the calendar month (formula on FX_Daily) | O6: Arithmetic mean of available daily observations in the calendar month (formula on FX_Daily) | P6: Arithmetic mean of available daily observations in the calendar month (formula on FX_Daily) | Q6: Number of FRED H.10 daily obs used | R6: "partial" if the month is not complete at the last FRED observation
A7: Unit | B7: South Korean Won to One U.S. Dollar | C7: Norwegian Kroner to One U.S. Dollar | D7: U.S. Dollars to One U.K. Pound Sterling | E7: U.S. Dollars to One Euro | F7: Chinese Yuan Renminbi to One U.S. Dollar | G7: Brazilian Reals to One U.S. Dollar | H7: Japanese Yen to One U.S. Dollar | I7: USD per 1 EUR | J7: NOK per 1 EUR | K7: KRW per 1 EUR | L7: GBP per 1 EUR | M7: CNY per 1 EUR | N7: BRL per 1 EUR | O7: JPY per 1 EUR | P7: NOK per 1 USD | Q7: days
A8: Frequency | B8: Monthly (average of daily) | C8: Monthly (average of daily) | D8: Monthly (average of daily) | E8: Monthly (average of daily) | F8: Monthly (average of daily) | G8: Monthly (average of daily) | H8: Monthly (average of daily) | I8: Monthly (average of daily) | J8: Monthly (average of daily) | K8: Monthly (average of daily) | L8: Monthly (average of daily) | M8: Monthly (average of daily) | N8: Monthly (average of daily) | O8: Monthly (average of daily) | P8: Monthly (average of daily) | Q8: Monthly | R8: Monthly
A9: URL | B9: https://fred.stlouisfed.org/series/DEXKOUS | C9: https://fred.stlouisfed.org/series/DEXNOUS | D9: https://fred.stlouisfed.org/series/DEXUSUK | E9: https://fred.stlouisfed.org/series/DEXUSEU | F9: https://fred.stlouisfed.org/series/DEXCHUS | G9: https://fred.stlouisfed.org/series/DEXBZUS | H9: https://fred.stlouisfed.org/series/DEXJPUS | I9: https://data.ecb.europa.eu/data/datasets/EXR/EXR.D.USD.EUR.SP00.A | J9: https://data.ecb.europa.eu/data/datasets/EXR/EXR.D.NOK.EUR.SP00.A | K9: https://data.ecb.europa.eu/data/datasets/EXR/EXR.D.KRW.EUR.SP00.A | L9: https://data.ecb.europa.eu/data/datasets/EXR/EXR.D.GBP.EUR.SP00.A | M9: https://data.ecb.europa.eu/data/datasets/EXR/EXR.D.CNY.EUR.SP00.A | N9: https://data.ecb.europa.eu/data/datasets/EXR/EXR.D.BRL.EUR.SP00.A | O9: https://data.ecb.europa.eu/data/datasets/EXR/EXR.D.JPY.EUR.SP00.A | P9: https://data.norges-bank.no/api/data/EXR/B.USD.NOK.SP?format=csv
A10: First observation (formula) | B10: =IFERROR(_xlfn.MINIFS($A$15:$A$144,B$15:B$144,">=-1E+99"),"N/A") -> 42370 | C10: =IFERROR(_xlfn.MINIFS($A$15:$A$144,C$15:C$144,">=-1E+99"),"N/A") -> 42370 | D10: =IFERROR(_xlfn.MINIFS($A$15:$A$144,D$15:D$144,">=-1E+99"),"N/A") -> 42370 | E10: =IFERROR(_xlfn.MINIFS($A$15:$A$144,E$15:E$144,">=-1E+99"),"N/A") -> 42370 | F10: =IFERROR(_xlfn.MINIFS($A$15:$A$144,F$15:F$144,">=-1E+99"),"N/A") -> 42370 | G10: =IFERROR(_xlfn.MINIFS($A$15:$A$144,G$15:G$144,">=-1E+99"),"N/A") -> 42370 | H10: =IFERROR(_xlfn.MINIFS($A$15:$A$144,H$15:H$144,">=-1E+99"),"N/A") -> 42370 | I10: =IFERROR(_xlfn.MINIFS($A$15:$A$144,I$15:I$144,">=-1E+99"),"N/A") -> 42370 | ... R10: =IFERROR(_xlfn.MINIFS($A$15:$A$144,R$15:R$144,">=-1E+99"),"N/A") -> 0
A11: Last observation (formula) | B11: =IFERROR(_xlfn.MAXIFS($A$15:$A$144,B$15:B$144,">=-1E+99"),"N/A") -> 46296 | C11: =IFERROR(_xlfn.MAXIFS($A$15:$A$144,C$15:C$144,">=-1E+99"),"N/A") -> 46296 | D11: =IFERROR(_xlfn.MAXIFS($A$15:$A$144,D$15:D$144,">=-1E+99"),"N/A") -> 46296 | E11: =IFERROR(_xlfn.MAXIFS($A$15:$A$144,E$15:E$144,">=-1E+99"),"N/A") -> 46296 | F11: =IFERROR(_xlfn.MAXIFS($A$15:$A$144,F$15:F$144,">=-1E+99"),"N/A") -> 46296 | G11: =IFERROR(_xlfn.MAXIFS($A$15:$A$144,G$15:G$144,">=-1E+99"),"N/A") -> 46296 | H11: =IFERROR(_xlfn.MAXIFS($A$15:$A$144,H$15:H$144,">=-1E+99"),"N/A") -> 46296 | I11: =IFERROR(_xlfn.MAXIFS($A$15:$A$144,I$15:I$144,">=-1E+99"),"N/A") -> 46296 | ... R11: =IFERROR(_xlfn.MAXIFS($A$15:$A$144,R$15:R$144,">=-1E+99"),"N/A") -> 0
A12: Last value (formula) | B12: =IFERROR(INDEX(B$15:B$144,MATCH(B11,$A$15:$A$144,0)),"N/A") -> 1355.29 | C12: =IFERROR(INDEX(C$15:C$144,MATCH(C11,$A$15:$A$144,0)),"N/A") -> 9.6386 | D12: =IFERROR(INDEX(D$15:D$144,MATCH(D11,$A$15:$A$144,0)),"N/A") -> 1.3215 | E12: =IFERROR(INDEX(E$15:E$144,MATCH(E11,$A$15:$A$144,0)),"N/A") -> 1.12455 | F12: =IFERROR(INDEX(F$15:F$144,MATCH(F11,$A$15:$A$144,0)),"N/A") -> 6.7038 | G12: =IFERROR(INDEX(G$15:G$144,MATCH(G11,$A$15:$A$144,0)),"N/A") -> 5.22755 | H12: =IFERROR(INDEX(H$15:H$144,MATCH(H11,$A$15:$A$144,0)),"N/A") -> 157.72 | I12: =IFERROR(INDEX(I$15:I$144,MATCH(I11,$A$15:$A$144,0)),"N/A") -> 1.1249 | ... R12: =IFERROR(INDEX(R$15:R$144,MATCH(R11,$A$15:$A$144,0)),"N/A") -> N/A
A13: Observations (count, formula) | B13: =COUNT(B$15:B$144) -> 130 | C13: =COUNT(C$15:C$144) -> 130 | D13: =COUNT(D$15:D$144) -> 130 | E13: =COUNT(E$15:E$144) -> 130 | F13: =COUNT(F$15:F$144) -> 130 | G13: =COUNT(G$15:G$144) -> 130 | H13: =COUNT(H$15:H$144) -> 130 | I13: =COUNT(I$15:I$144) -> 130 | ... R13: =COUNT(R$15:R$144) -> 0
A14: Month (first day) | B14: KRW per USD — monthly avg | C14: NOK per USD — monthly avg | D14: USD per GBP — monthly avg | E14: USD per EUR — monthly avg | F14: CNY per USD — monthly avg | G14: BRL per USD (reference only) — monthly avg | H14: JPY per USD (reference only) — monthly avg | I14: USD per EUR (ECB ref.) — monthly avg | J14: NOK per EUR (ECB ref.) — monthly avg | K14: KRW per EUR (ECB ref.) — monthly avg | L14: GBP per EUR (ECB ref.) — monthly avg | M14: CNY per EUR (ECB ref.) — monthly avg | N14: BRL per EUR (ECB ref.) — monthly avg | O14: JPY per EUR (ECB ref.) — monthly avg | P14: NOK per USD (Norges Bank) — monthly avg | Q14: Trading days in month (DEXNOUS obs) | R14: Month status
A15: 42370 | B15: =IFERROR(AVERAGEIFS(FX_Daily!B$15:B$2821,FX_Daily!$A$15:$A$2821,">="&$A15,FX_Daily!$A$15:$A$2821,"<="&EOMONTH($A15,0)),"") -> 1203.3179 | C15: =IFERROR(AVERAGEIFS(FX_Daily!C$15:C$2821,FX_Daily!$A$15:$A$2821,">="&$A15,FX_Daily!$A$15:$A$2821,"<="&EOMONTH($A15,0)),"") -> 8.8193737 | D15: =IFERROR(AVERAGEIFS(FX_Daily!D$15:D$2821,FX_Daily!$A$15:$A$2821,">="&$A15,FX_Daily!$A$15:$A$2821,"<="&EOMONTH($A15,0)),"") -> 1.4391579 | E15: =IFERROR(AVERAGEIFS(FX_Daily!E$15:E$2821,FX_Daily!$A$15:$A$2821,">="&$A15,FX_Daily!$A$15:$A$2821,"<="&EOMONTH($A15,0)),"") -> 1.0855053 | F15: =IFERROR(AVERAGEIFS(FX_Daily!F$15:F$2821,FX_Daily!$A$15:$A$2821,">="&$A15,FX_Daily!$A$15:$A$2821,"<="&EOMONTH($A15,0)),"") -> 6.5726 | G15: =IFERROR(AVERAGEIFS(FX_Daily!G$15:G$2821,FX_Daily!$A$15:$A$2821,">="&$A15,FX_Daily!$A$15:$A$2821,"<="&EOMONTH($A15,0)),"") -> 4.0555895 | H15: =IFERROR(AVERAGEIFS(FX_Daily!H$15:H$2821,FX_Daily!$A$15:$A$2821,">="&$A15,FX_Daily!$A$15:$A$2821,"<="&EOMONTH($A15,0)),"") -> 118.22579 | I15: =IFERROR(AVERAGEIFS(FX_Daily!I$15:I$2821,FX_Daily!$A$15:$A$2821,">="&$A15,FX_Daily!$A$15:$A$2821,"<="&EOMONTH($A15,0)),"") -> 1.085965 | ... P15: =IFERROR(AVERAGEIFS(FX_Daily!P$15:P$2821,FX_Daily!$A$15:$A$2821,">="&$A15,FX_Daily!$A$15:$A$2821,"<="&EOMONTH($A15,0)),"") -> 8.830905 | Q15: =COUNTIFS(FX_Daily!$A$15:$A$2821,">="&$A15,FX_Daily!$A$15:$A$2821,"<="&EOMONTH($A15,0),FX_Daily!C$15:C$2821,">0") -> 19 | R15: =IF(EOMONTH($A15,0)>FX_Daily!$C$11,"partial month","complete") -> complete
A16: 42401 | B16: =IFERROR(AVERAGEIFS(FX_Daily!B$15:B$2821,FX_Daily!$A$15:$A$2821,">="&$A16,FX_Daily!$A$15:$A$2821,"<="&EOMONTH($A16,0)),"") -> 1216.2285 | C16: =IFERROR(AVERAGEIFS(FX_Daily!C$15:C$2821,FX_Daily!$A$15:$A$2821,">="&$A16,FX_Daily!$A$15:$A$2821,"<="&EOMONTH($A16,0)),"") -> 8.612745 | D16: =IFERROR(AVERAGEIFS(FX_Daily!D$15:D$2821,FX_Daily!$A$15:$A$2821,">="&$A16,FX_Daily!$A$15:$A$2821,"<="&EOMONTH($A16,0)),"") -> 1.429005 | E16: =IFERROR(AVERAGEIFS(FX_Daily!E$15:E$2821,FX_Daily!$A$15:$A$2821,">="&$A16,FX_Daily!$A$15:$A$2821,"<="&EOMONTH($A16,0)),"") -> 1.10923 | F16: =IFERROR(AVERAGEIFS(FX_Daily!F$15:F$2821,FX_Daily!$A$15:$A$2821,">="&$A16,FX_Daily!$A$15:$A$2821,"<="&EOMONTH($A16,0)),"") -> 6.55005 | G16: =IFERROR(AVERAGEIFS(FX_Daily!G$15:G$2821,FX_Daily!$A$15:$A$2821,">="&$A16,FX_Daily!$A$15:$A$2821,"<="&EOMONTH($A16,0)),"") -> 3.964385 | H16: =IFERROR(AVERAGEIFS(FX_Daily!H$15:H$2821,FX_Daily!$A$15:$A$2821,">="&$A16,FX_Daily!$A$15:$A$2821,"<="&EOMONTH($A16,0)),"") -> 114.6155 | I16: =IFERROR(AVERAGEIFS(FX_Daily!I$15:I$2821,FX_Daily!$A$15:$A$2821,">="&$A16,FX_Daily!$A$15:$A$2821,"<="&EOMONTH($A16,0)),"") -> 1.1092952 | ... P16: =IFERROR(AVERAGEIFS(FX_Daily!P$15:P$2821,FX_Daily!$A$15:$A$2821,">="&$A16,FX_Daily!$A$15:$A$2821,"<="&EOMONTH($A16,0)),"") -> 8.6212 | Q16: =COUNTIFS(FX_Daily!$A$15:$A$2821,">="&$A16,FX_Daily!$A$15:$A$2821,"<="&EOMONTH($A16,0),FX_Daily!C$15:C$2821,">0") -> 20 | R16: =IF(EOMONTH($A16,0)>FX_Daily!$C$11,"partial month","complete") -> complete
A17: 42430 | B17: =IFERROR(AVERAGEIFS(FX_Daily!B$15:B$2821,FX_Daily!$A$15:$A$2821,">="&$A17,FX_Daily!$A$15:$A$2821,"<="&EOMONTH($A17,0)),"") -> 1181.573 | C17: =IFERROR(AVERAGEIFS(FX_Daily!C$15:C$2821,FX_Daily!$A$15:$A$2821,">="&$A17,FX_Daily!$A$15:$A$2821,"<="&EOMONTH($A17,0)),"") -> 8.4754087 | D17: =IFERROR(AVERAGEIFS(FX_Daily!D$15:D$2821,FX_Daily!$A$15:$A$2821,">="&$A17,FX_Daily!$A$15:$A$2821,"<="&EOMONTH($A17,0)),"") -> 1.4249304 | E17: =IFERROR(AVERAGEIFS(FX_Daily!E$15:E$2821,FX_Daily!$A$15:$A$2821,">="&$A17,FX_Daily!$A$15:$A$2821,"<="&EOMONTH($A17,0)),"") -> 1.1133522 | F17: =IFERROR(AVERAGEIFS(FX_Daily!F$15:F$2821,FX_Daily!$A$15:$A$2821,">="&$A17,FX_Daily!$A$15:$A$2821,"<="&EOMONTH($A17,0)),"") -> 6.5026913 | G17: =IFERROR(AVERAGEIFS(FX_Daily!G$15:G$2821,FX_Daily!$A$15:$A$2821,">="&$A17,FX_Daily!$A$15:$A$2821,"<="&EOMONTH($A17,0)),"") -> 3.6980217 | H17: =IFERROR(AVERAGEIFS(FX_Daily!H$15:H$2821,FX_Daily!$A$15:$A$2821,">="&$A17,FX_Daily!$A$15:$A$2821,"<="&EOMONTH($A17,0)),"") -> 112.93174 | I17: =IFERROR(AVERAGEIFS(FX_Daily!I$15:I$2821,FX_Daily!$A$15:$A$2821,">="&$A17,FX_Daily!$A$15:$A$2821,"<="&EOMONTH($A17,0)),"") -> 1.1099667 | ... P17: =IFERROR(AVERAGEIFS(FX_Daily!P$15:P$2821,FX_Daily!$A$15:$A$2821,">="&$A17,FX_Daily!$A$15:$A$2821,"<="&EOMONTH($A17,0)),"") -> 8.49374 | Q17: =COUNTIFS(FX_Daily!$A$15:$A$2821,">="&$A17,FX_Daily!$A$15:$A$2821,"<="&EOMONTH($A17,0),FX_Daily!C$15:C$2821,">0") -> 23 | R17: =IF(EOMONTH($A17,0)>FX_Daily!$C$11,"partial month","complete") -> complete
A18: 42461 | B18: =IFERROR(AVERAGEIFS(FX_Daily!B$15:B$2821,FX_Daily!$A$15:$A$2821,">="&$A18,FX_Daily!$A$15:$A$2821,"<="&EOMONTH($A18,0)),"") -> 1145.7967 | C18: =IFERROR(AVERAGEIFS(FX_Daily!C$15:C$2821,FX_Daily!$A$15:$A$2821,">="&$A18,FX_Daily!$A$15:$A$2821,"<="&EOMONTH($A18,0)),"") -> 8.2081762 | D18: =IFERROR(AVERAGEIFS(FX_Daily!D$15:D$2821,FX_Daily!$A$15:$A$2821,">="&$A18,FX_Daily!$A$15:$A$2821,"<="&EOMONTH($A18,0)),"") -> 1.4318619 | E18: =IFERROR(AVERAGEIFS(FX_Daily!E$15:E$2821,FX_Daily!$A$15:$A$2821,">="&$A18,FX_Daily!$A$15:$A$2821,"<="&EOMONTH($A18,0)),"") -> 1.1345667 | F18: =IFERROR(AVERAGEIFS(FX_Daily!F$15:F$2821,FX_Daily!$A$15:$A$2821,">="&$A18,FX_Daily!$A$15:$A$2821,"<="&EOMONTH($A18,0)),"") -> 6.4754333 | G18: =IFERROR(AVERAGEIFS(FX_Daily!G$15:G$2821,FX_Daily!$A$15:$A$2821,">="&$A18,FX_Daily!$A$15:$A$2821,"<="&EOMONTH($A18,0)),"") -> 3.5634476 | H18: =IFERROR(AVERAGEIFS(FX_Daily!H$15:H$2821,FX_Daily!$A$15:$A$2821,">="&$A18,FX_Daily!$A$15:$A$2821,"<="&EOMONTH($A18,0)),"") -> 109.5519 | I18: =IFERROR(AVERAGEIFS(FX_Daily!I$15:I$2821,FX_Daily!$A$15:$A$2821,">="&$A18,FX_Daily!$A$15:$A$2821,"<="&EOMONTH($A18,0)),"") -> 1.133919 | ... P18: =IFERROR(AVERAGEIFS(FX_Daily!P$15:P$2821,FX_Daily!$A$15:$A$2821,">="&$A18,FX_Daily!$A$15:$A$2821,"<="&EOMONTH($A18,0)),"") -> 8.2213905 | Q18: =COUNTIFS(FX_Daily!$A$15:$A$2821,">="&$A18,FX_Daily!$A$15:$A$2821,"<="&EOMONTH($A18,0),FX_Daily!C$15:C$2821,">0") -> 21 | R18: =IF(EOMONTH($A18,0)>FX_Daily!$C$11,"partial month","complete") -> complete
A19: 42491 | B19: =IFERROR(AVERAGEIFS(FX_Daily!B$15:B$2821,FX_Daily!$A$15:$A$2821,">="&$A19,FX_Daily!$A$15:$A$2821,"<="&EOMONTH($A19,0)),"") -> 1173.7905 | C19: =IFERROR(AVERAGEIFS(FX_Daily!C$15:C$2821,FX_Daily!$A$15:$A$2821,">="&$A19,FX_Daily!$A$15:$A$2821,"<="&EOMONTH($A19,0)),"") -> 8.226919 | D19: =IFERROR(AVERAGEIFS(FX_Daily!D$15:D$2821,FX_Daily!$A$15:$A$2821,">="&$A19,FX_Daily!$A$15:$A$2821,"<="&EOMONTH($A19,0)),"") -> 1.4524429 | E19: =IFERROR(AVERAGEIFS(FX_Daily!E$15:E$2821,FX_Daily!$A$15:$A$2821,">="&$A19,FX_Daily!$A$15:$A$2821,"<="&EOMONTH($A19,0)),"") -> 1.1312048 | F19: =IFERROR(AVERAGEIFS(FX_Daily!F$15:F$2821,FX_Daily!$A$15:$A$2821,">="&$A19,FX_Daily!$A$15:$A$2821,"<="&EOMONTH($A19,0)),"") -> 6.525881 | G19: =IFERROR(AVERAGEIFS(FX_Daily!G$15:G$2821,FX_Daily!$A$15:$A$2821,">="&$A19,FX_Daily!$A$15:$A$2821,"<="&EOMONTH($A19,0)),"") -> 3.5403048 | H19: =IFERROR(AVERAGEIFS(FX_Daily!H$15:H$2821,FX_Daily!$A$15:$A$2821,">="&$A19,FX_Daily!$A$15:$A$2821,"<="&EOMONTH($A19,0)),"") -> 108.8481 | I19: =IFERROR(AVERAGEIFS(FX_Daily!I$15:I$2821,FX_Daily!$A$15:$A$2821,">="&$A19,FX_Daily!$A$15:$A$2821,"<="&EOMONTH($A19,0)),"") -> 1.1311091 | ... P19: =IFERROR(AVERAGEIFS(FX_Daily!P$15:P$2821,FX_Daily!$A$15:$A$2821,">="&$A19,FX_Daily!$A$15:$A$2821,"<="&EOMONTH($A19,0)),"") -> 8.2375947 | Q19: =COUNTIFS(FX_Daily!$A$15:$A$2821,">="&$A19,FX_Daily!$A$15:$A$2821,"<="&EOMONTH($A19,0),FX_Daily!C$15:C$2821,">0") -> 21 | R19: =IF(EOMONTH($A19,0)>FX_Daily!$C$11,"partial month","complete") -> complete
A20: 42522 | B20: =IFERROR(AVERAGEIFS(FX_Daily!B$15:B$2821,FX_Daily!$A$15:$A$2821,">="&$A20,FX_Daily!$A$15:$A$2821,"<="&EOMONTH($A20,0)),"") -> 1165.2023 | C20: =IFERROR(AVERAGEIFS(FX_Daily!C$15:C$2821,FX_Daily!$A$15:$A$2821,">="&$A20,FX_Daily!$A$15:$A$2821,"<="&EOMONTH($A20,0)),"") -> 8.3064 | D20: =IFERROR(AVERAGEIFS(FX_Daily!D$15:D$2821,FX_Daily!$A$15:$A$2821,">="&$A20,FX_Daily!$A$15:$A$2821,"<="&EOMONTH($A20,0)),"") -> 1.4197364 | E20: =IFERROR(AVERAGEIFS(FX_Daily!E$15:E$2821,FX_Daily!$A$15:$A$2821,">="&$A20,FX_Daily!$A$15:$A$2821,"<="&EOMONTH($A20,0)),"") -> 1.1231773 | F20: =IFERROR(AVERAGEIFS(FX_Daily!F$15:F$2821,FX_Daily!$A$15:$A$2821,">="&$A20,FX_Daily!$A$15:$A$2821,"<="&EOMONTH($A20,0)),"") -> 6.5892227 | G20: =IFERROR(AVERAGEIFS(FX_Daily!G$15:G$2821,FX_Daily!$A$15:$A$2821,">="&$A20,FX_Daily!$A$15:$A$2821,"<="&EOMONTH($A20,0)),"") -> 3.4234455 | H20: =IFERROR(AVERAGEIFS(FX_Daily!H$15:H$2821,FX_Daily!$A$15:$A$2821,">="&$A20,FX_Daily!$A$15:$A$2821,"<="&EOMONTH($A20,0)),"") -> 105.35091 | I20: =IFERROR(AVERAGEIFS(FX_Daily!I$15:I$2821,FX_Daily!$A$15:$A$2821,">="&$A20,FX_Daily!$A$15:$A$2821,"<="&EOMONTH($A20,0)),"") -> 1.1228909 | ... P20: =IFERROR(AVERAGEIFS(FX_Daily!P$15:P$2821,FX_Daily!$A$15:$A$2821,">="&$A20,FX_Daily!$A$15:$A$2821,"<="&EOMONTH($A20,0)),"") -> 8.3080182 | Q20: =COUNTIFS(FX_Daily!$A$15:$A$2821,">="&$A20,FX_Daily!$A$15:$A$2821,"<="&EOMONTH($A20,0),FX_Daily!C$15:C$2821,">0") -> 22 | R20: =IF(EOMONTH($A20,0)>FX_Daily!$C$11,"partial month","complete") -> complete
A21: 42552 | B21: =IFERROR(AVERAGEIFS(FX_Daily!B$15:B$2821,FX_Daily!$A$15:$A$2821,">="&$A21,FX_Daily!$A$15:$A$2821,"<="&EOMONTH($A21,0)),"") -> 1140.865 | C21: =IFERROR(AVERAGEIFS(FX_Daily!C$15:C$2821,FX_Daily!$A$15:$A$2821,">="&$A21,FX_Daily!$A$15:$A$2821,"<="&EOMONTH($A21,0)),"") -> 8.479475 | D21: =IFERROR(AVERAGEIFS(FX_Daily!D$15:D$2821,FX_Daily!$A$15:$A$2821,">="&$A21,FX_Daily!$A$15:$A$2821,"<="&EOMONTH($A21,0)),"") -> 1.31341 | E21: =IFERROR(AVERAGEIFS(FX_Daily!E$15:E$2821,FX_Daily!$A$15:$A$2821,">="&$A21,FX_Daily!$A$15:$A$2821,"<="&EOMONTH($A21,0)),"") -> 1.105495 | F21: =IFERROR(AVERAGEIFS(FX_Daily!F$15:F$2821,FX_Daily!$A$15:$A$2821,">="&$A21,FX_Daily!$A$15:$A$2821,"<="&EOMONTH($A21,0)),"") -> 6.677105 | G21: =IFERROR(AVERAGEIFS(FX_Daily!G$15:G$2821,FX_Daily!$A$15:$A$2821,">="&$A21,FX_Daily!$A$15:$A$2821,"<="&EOMONTH($A21,0)),"") -> 3.27814 | H21: =IFERROR(AVERAGEIFS(FX_Daily!H$15:H$2821,FX_Daily!$A$15:$A$2821,">="&$A21,FX_Daily!$A$15:$A$2821,"<="&EOMONTH($A21,0)),"") -> 104.191 | I21: =IFERROR(AVERAGEIFS(FX_Daily!I$15:I$2821,FX_Daily!$A$15:$A$2821,">="&$A21,FX_Daily!$A$15:$A$2821,"<="&EOMONTH($A21,0)),"") -> 1.1068524 | ... P21: =IFERROR(AVERAGEIFS(FX_Daily!P$15:P$2821,FX_Daily!$A$15:$A$2821,">="&$A21,FX_Daily!$A$15:$A$2821,"<="&EOMONTH($A21,0)),"") -> 8.4648286 | Q21: =COUNTIFS(FX_Daily!$A$15:$A$2821,">="&$A21,FX_Daily!$A$15:$A$2821,"<="&EOMONTH($A21,0),FX_Daily!C$15:C$2821,">0") -> 20 | R21: =IF(EOMONTH($A21,0)>FX_Daily!$C$11,"partial month","complete") -> complete
A22: 42583 | B22: =IFERROR(AVERAGEIFS(FX_Daily!B$15:B$2821,FX_Daily!$A$15:$A$2821,">="&$A22,FX_Daily!$A$15:$A$2821,"<="&EOMONTH($A22,0)),"") -> 1110.0183 | C22: =IFERROR(AVERAGEIFS(FX_Daily!C$15:C$2821,FX_Daily!$A$15:$A$2821,">="&$A22,FX_Daily!$A$15:$A$2821,"<="&EOMONTH($A22,0)),"") -> 8.3009261 | D22: =IFERROR(AVERAGEIFS(FX_Daily!D$15:D$2821,FX_Daily!$A$15:$A$2821,">="&$A22,FX_Daily!$A$15:$A$2821,"<="&EOMONTH($A22,0)),"") -> 1.3101478 | E22: =IFERROR(AVERAGEIFS(FX_Daily!E$15:E$2821,FX_Daily!$A$15:$A$2821,">="&$A22,FX_Daily!$A$15:$A$2821,"<="&EOMONTH($A22,0)),"") -> 1.1206522 | F22: =IFERROR(AVERAGEIFS(FX_Daily!F$15:F$2821,FX_Daily!$A$15:$A$2821,">="&$A22,FX_Daily!$A$15:$A$2821,"<="&EOMONTH($A22,0)),"") -> 6.6465739 | G22: =IFERROR(AVERAGEIFS(FX_Daily!G$15:G$2821,FX_Daily!$A$15:$A$2821,">="&$A22,FX_Daily!$A$15:$A$2821,"<="&EOMONTH($A22,0)),"") -> 3.2085522 | H22: =IFERROR(AVERAGEIFS(FX_Daily!H$15:H$2821,FX_Daily!$A$15:$A$2821,">="&$A22,FX_Daily!$A$15:$A$2821,"<="&EOMONTH($A22,0)),"") -> 101.23826 | I22: =IFERROR(AVERAGEIFS(FX_Daily!I$15:I$2821,FX_Daily!$A$15:$A$2821,">="&$A22,FX_Daily!$A$15:$A$2821,"<="&EOMONTH($A22,0)),"") -> 1.1211739 | ... P22: =IFERROR(AVERAGEIFS(FX_Daily!P$15:P$2821,FX_Daily!$A$15:$A$2821,">="&$A22,FX_Daily!$A$15:$A$2821,"<="&EOMONTH($A22,0)),"") -> 8.298113 | Q22: =COUNTIFS(FX_Daily!$A$15:$A$2821,">="&$A22,FX_Daily!$A$15:$A$2821,"<="&EOMONTH($A22,0),FX_Daily!C$15:C$2821,">0") -> 23 | R22: =IF(EOMONTH($A22,0)>FX_Daily!$C$11,"partial month","complete") -> complete
A23: 42614 | B23: =IFERROR(AVERAGEIFS(FX_Daily!B$15:B$2821,FX_Daily!$A$15:$A$2821,">="&$A23,FX_Daily!$A$15:$A$2821,"<="&EOMONTH($A23,0)),"") -> 1108.3638 | C23: =IFERROR(AVERAGEIFS(FX_Daily!C$15:C$2821,FX_Daily!$A$15:$A$2821,">="&$A23,FX_Daily!$A$15:$A$2821,"<="&EOMONTH($A23,0)),"") -> 8.1957238 | D23: =IFERROR(AVERAGEIFS(FX_Daily!D$15:D$2821,FX_Daily!$A$15:$A$2821,">="&$A23,FX_Daily!$A$15:$A$2821,"<="&EOMONTH($A23,0)),"") -> 1.3140143 | E23: =IFERROR(AVERAGEIFS(FX_Daily!E$15:E$2821,FX_Daily!$A$15:$A$2821,">="&$A23,FX_Daily!$A$15:$A$2821,"<="&EOMONTH($A23,0)),"") -> 1.121781 | F23: =IFERROR(AVERAGEIFS(FX_Daily!F$15:F$2821,FX_Daily!$A$15:$A$2821,">="&$A23,FX_Daily!$A$15:$A$2821,"<="&EOMONTH($A23,0)),"") -> 6.670181 | G23: =IFERROR(AVERAGEIFS(FX_Daily!G$15:G$2821,FX_Daily!$A$15:$A$2821,">="&$A23,FX_Daily!$A$15:$A$2821,"<="&EOMONTH($A23,0)),"") -> 3.253181 | H23: =IFERROR(AVERAGEIFS(FX_Daily!H$15:H$2821,FX_Daily!$A$15:$A$2821,">="&$A23,FX_Daily!$A$15:$A$2821,"<="&EOMONTH($A23,0)),"") -> 101.78429 | I23: =IFERROR(AVERAGEIFS(FX_Daily!I$15:I$2821,FX_Daily!$A$15:$A$2821,">="&$A23,FX_Daily!$A$15:$A$2821,"<="&EOMONTH($A23,0)),"") -> 1.1212091 | ... P23: =IFERROR(AVERAGEIFS(FX_Daily!P$15:P$2821,FX_Daily!$A$15:$A$2821,">="&$A23,FX_Daily!$A$15:$A$2821,"<="&EOMONTH($A23,0)),"") -> 8.2029682 | Q23: =COUNTIFS(FX_Daily!$A$15:$A$2821,">="&$A23,FX_Daily!$A$15:$A$2821,"<="&EOMONTH($A23,0),FX_Daily!C$15:C$2821,">0") -> 21 | R23: =IF(EOMONTH($A23,0)>FX_Daily!$C$11,"partial month","complete") -> complete
A24: 42644 | B24: =IFERROR(AVERAGEIFS(FX_Daily!B$15:B$2821,FX_Daily!$A$15:$A$2821,">="&$A24,FX_Daily!$A$15:$A$2821,"<="&EOMONTH($A24,0)),"") -> 1128.166 | C24: =IFERROR(AVERAGEIFS(FX_Daily!C$15:C$2821,FX_Daily!$A$15:$A$2821,">="&$A24,FX_Daily!$A$15:$A$2821,"<="&EOMONTH($A24,0)),"") -> 8.17221 | D24: =IFERROR(AVERAGEIFS(FX_Daily!D$15:D$2821,FX_Daily!$A$15:$A$2821,">="&$A24,FX_Daily!$A$15:$A$2821,"<="&EOMONTH($A24,0)),"") -> 1.23299 | E24: =IFERROR(AVERAGEIFS(FX_Daily!E$15:E$2821,FX_Daily!$A$15:$A$2821,">="&$A24,FX_Daily!$A$15:$A$2821,"<="&EOMONTH($A24,0)),"") -> 1.10144 | F24: =IFERROR(AVERAGEIFS(FX_Daily!F$15:F$2821,FX_Daily!$A$15:$A$2821,">="&$A24,FX_Daily!$A$15:$A$2821,"<="&EOMONTH($A24,0)),"") -> 6.73031 | G24: =IFERROR(AVERAGEIFS(FX_Daily!G$15:G$2821,FX_Daily!$A$15:$A$2821,">="&$A24,FX_Daily!$A$15:$A$2821,"<="&EOMONTH($A24,0)),"") -> 3.185395 | H24: =IFERROR(AVERAGEIFS(FX_Daily!H$15:H$2821,FX_Daily!$A$15:$A$2821,">="&$A24,FX_Daily!$A$15:$A$2821,"<="&EOMONTH($A24,0)),"") -> 103.9075 | I24: =IFERROR(AVERAGEIFS(FX_Daily!I$15:I$2821,FX_Daily!$A$15:$A$2821,">="&$A24,FX_Daily!$A$15:$A$2821,"<="&EOMONTH($A24,0)),"") -> 1.1026048 | ... P24: =IFERROR(AVERAGEIFS(FX_Daily!P$15:P$2821,FX_Daily!$A$15:$A$2821,">="&$A24,FX_Daily!$A$15:$A$2821,"<="&EOMONTH($A24,0)),"") -> 8.1642 | Q24: =COUNTIFS(FX_Daily!$A$15:$A$2821,">="&$A24,FX_Daily!$A$15:$A$2821,"<="&EOMONTH($A24,0),FX_Daily!C$15:C$2821,">0") -> 20 | R24: =IF(EOMONTH($A24,0)>FX_Daily!$C$11,"partial month","complete") -> complete
A25: 42675 | B25: =IFERROR(AVERAGEIFS(FX_Daily!B$15:B$2821,FX_Daily!$A$15:$A$2821,">="&$A25,FX_Daily!$A$15:$A$2821,"<="&EOMONTH($A25,0)),"") -> 1162.708 | C25: =IFERROR(AVERAGEIFS(FX_Daily!C$15:C$2821,FX_Daily!$A$15:$A$2821,">="&$A25,FX_Daily!$A$15:$A$2821,"<="&EOMONTH($A25,0)),"") -> 8.41466 | D25: =IFERROR(AVERAGEIFS(FX_Daily!D$15:D$2821,FX_Daily!$A$15:$A$2821,">="&$A25,FX_Daily!$A$15:$A$2821,"<="&EOMONTH($A25,0)),"") -> 1.24319 | E25: =IFERROR(AVERAGEIFS(FX_Daily!E$15:E$2821,FX_Daily!$A$15:$A$2821,">="&$A25,FX_Daily!$A$15:$A$2821,"<="&EOMONTH($A25,0)),"") -> 1.07918 | F25: =IFERROR(AVERAGEIFS(FX_Daily!F$15:F$2821,FX_Daily!$A$15:$A$2821,">="&$A25,FX_Daily!$A$15:$A$2821,"<="&EOMONTH($A25,0)),"") -> 6.84016 | G25: =IFERROR(AVERAGEIFS(FX_Daily!G$15:G$2821,FX_Daily!$A$15:$A$2821,">="&$A25,FX_Daily!$A$15:$A$2821,"<="&EOMONTH($A25,0)),"") -> 3.33689 | H25: =IFERROR(AVERAGEIFS(FX_Daily!H$15:H$2821,FX_Daily!$A$15:$A$2821,">="&$A25,FX_Daily!$A$15:$A$2821,"<="&EOMONTH($A25,0)),"") -> 108.443 | I25: =IFERROR(AVERAGEIFS(FX_Daily!I$15:I$2821,FX_Daily!$A$15:$A$2821,">="&$A25,FX_Daily!$A$15:$A$2821,"<="&EOMONTH($A25,0)),"") -> 1.0798955 | ... P25: =IFERROR(AVERAGEIFS(FX_Daily!P$15:P$2821,FX_Daily!$A$15:$A$2821,">="&$A25,FX_Daily!$A$15:$A$2821,"<="&EOMONTH($A25,0)),"") -> 8.4116318 | Q25: =COUNTIFS(FX_Daily!$A$15:$A$2821,">="&$A25,FX_Daily!$A$15:$A$2821,"<="&EOMONTH($A25,0),FX_Daily!C$15:C$2821,">0") -> 20 | R25: =IF(EOMONTH($A25,0)>FX_Daily!$C$11,"partial month","complete") -> complete
A26: 42705 | B26: =IFERROR(AVERAGEIFS(FX_Daily!B$15:B$2821,FX_Daily!$A$15:$A$2821,">="&$A26,FX_Daily!$A$15:$A$2821,"<="&EOMONTH($A26,0)),"") -> 1183.07 | C26: =IFERROR(AVERAGEIFS(FX_Daily!C$15:C$2821,FX_Daily!$A$15:$A$2821,">="&$A26,FX_Daily!$A$15:$A$2821,"<="&EOMONTH($A26,0)),"") -> 8.5617429 | D26: =IFERROR(AVERAGEIFS(FX_Daily!D$15:D$2821,FX_Daily!$A$15:$A$2821,">="&$A26,FX_Daily!$A$15:$A$2821,"<="&EOMONTH($A26,0)),"") -> 1.2482524 | E26: =IFERROR(AVERAGEIFS(FX_Daily!E$15:E$2821,FX_Daily!$A$15:$A$2821,">="&$A26,FX_Daily!$A$15:$A$2821,"<="&EOMONTH($A26,0)),"") -> 1.0544619 | F26: =IFERROR(AVERAGEIFS(FX_Daily!F$15:F$2821,FX_Daily!$A$15:$A$2821,">="&$A26,FX_Daily!$A$15:$A$2821,"<="&EOMONTH($A26,0)),"") -> 6.9197524 | G26: =IFERROR(AVERAGEIFS(FX_Daily!G$15:G$2821,FX_Daily!$A$15:$A$2821,">="&$A26,FX_Daily!$A$15:$A$2821,"<="&EOMONTH($A26,0)),"") -> 3.3539667 | H26: =IFERROR(AVERAGEIFS(FX_Daily!H$15:H$2821,FX_Daily!$A$15:$A$2821,">="&$A26,FX_Daily!$A$15:$A$2821,"<="&EOMONTH($A26,0)),"") -> 115.9981 | I26: =IFERROR(AVERAGEIFS(FX_Daily!I$15:I$2821,FX_Daily!$A$15:$A$2821,">="&$A26,FX_Daily!$A$15:$A$2821,"<="&EOMONTH($A26,0)),"") -> 1.0542905 | ... P26: =IFERROR(AVERAGEIFS(FX_Daily!P$15:P$2821,FX_Daily!$A$15:$A$2821,">="&$A26,FX_Daily!$A$15:$A$2821,"<="&EOMONTH($A26,0)),"") -> 8.5619714 | Q26: =COUNTIFS(FX_Daily!$A$15:$A$2821,">="&$A26,FX_Daily!$A$15:$A$2821,"<="&EOMONTH($A26,0),FX_Daily!C$15:C$2821,">0") -> 21 | R26: =IF(EOMONTH($A26,0)>FX_Daily!$C$11,"partial month","complete") -> complete
... A144: 46296 | B144: =IFERROR(AVERAGEIFS(FX_Daily!B$15:B$2821,FX_Daily!$A$15:$A$2821,">="&$A144,FX_Daily!$A$15:$A$2821,"<="&EOMONTH($A144,0)),"") -> 1355.29 | C144: =IFERROR(AVERAGEIFS(FX_Daily!C$15:C$2821,FX_Daily!$A$15:$A$2821,">="&$A144,FX_Daily!$A$15:$A$2821,"<="&EOMONTH($A144,0)),"") -> 9.6386 | D144: =IFERROR(AVERAGEIFS(FX_Daily!D$15:D$2821,FX_Daily!$A$15:$A$2821,">="&$A144,FX_Daily!$A$15:$A$2821,"<="&EOMONTH($A144,0)),"") -> 1.3215 | E144: =IFERROR(AVERAGEIFS(FX_Daily!E$15:E$2821,FX_Daily!$A$15:$A$2821,">="&$A144,FX_Daily!$A$15:$A$2821,"<="&EOMONTH($A144,0)),"") -> 1.12455 | F144: =IFERROR(AVERAGEIFS(FX_Daily!F$15:F$2821,FX_Daily!$A$15:$A$2821,">="&$A144,FX_Daily!$A$15:$A$2821,"<="&EOMONTH($A144,0)),"") -> 6.7038 | G144: =IFERROR(AVERAGEIFS(FX_Daily!G$15:G$2821,FX_Daily!$A$15:$A$2821,">="&$A144,FX_Daily!$A$15:$A$2821,"<="&EOMONTH($A144,0)),"") -> 5.22755 | H144: =IFERROR(AVERAGEIFS(FX_Daily!H$15:H$2821,FX_Daily!$A$15:$A$2821,">="&$A144,FX_Daily!$A$15:$A$2821,"<="&EOMONTH($A144,0)),"") -> 157.72 | I144: =IFERROR(AVERAGEIFS(FX_Daily!I$15:I$2821,FX_Daily!$A$15:$A$2821,">="&$A144,FX_Daily!$A$15:$A$2821,"<="&EOMONTH($A144,0)),"") -> 1.1249 | ... P144: =IFERROR(AVERAGEIFS(FX_Daily!P$15:P$2821,FX_Daily!$A$15:$A$2821,">="&$A144,FX_Daily!$A$15:$A$2821,"<="&EOMONTH($A144,0)),"") -> 9.6102 | Q144: =COUNTIFS(FX_Daily!$A$15:$A$2821,">="&$A144,FX_Daily!$A$15:$A$2821,"<="&EOMONTH($A144,0),FX_Daily!C$15:C$2821,">0") -> 2 | R144: =IF(EOMONTH($A144,0)>FX_Daily!$C$11,"partial month","complete") -> partial month

Sheet Rates_Daily
A1: Rates_Daily — daily interest rates used to build monthly averages (raw)
A2: As-of date: 2026-10-07 | Retrieval date: 2026-10-07 | Blue font = raw value from source; black = formula. Weekdays + weekend days on which a source published (e.g. China make-up working days for Shibor). Blank = no observation by that source on that date (holiday) or series not yet published (SOFR from 2018-04, €STR from 2019-10).
A4: Provider | B4: FRED (St. Louis Fed) | C4: FRED (St. Louis Fed) | D4: FRED (St. Louis Fed) | E4: European Central Bank (ECB Data Portal) | F4: European Central Bank (ECB Data Portal) | G4: Bank of England (IADB) | H4: Bank of England (IADB) | I4: Bank of England (yield curve data) | J4: Bank of England (yield curve data) | K4: Bank of England (yield curve data) | L4: Bank of England (yield curve data) | M4: CFETS / National Interbank Funding Center (chinamoney.com.cn) | N4: CFETS / National Interbank Funding Center (chinamoney.com.cn) | O4: CFETS / National Interbank Funding Center (chinamoney.com.cn) | P4: CFETS / National Interbank Funding Center (chinamoney.com.cn) | Q4: Norges Bank | R4: Norges Bank | S4: Banco Central do Brasil (SGS)
A5: Series ID / table | B5: SOFR | C5: DFEDTARU | D5: DFEDTARL | E5: EST.B.EU000A2X2A25.WT | F5: FM.D.U2.EUR.4F.KR.DFR.LEV | G5: IUDBEDR | H5: IUDSOIA | I5: UK OIS spot curve, 1M maturity | J5: UK OIS spot curve, 3M maturity | K5: UK OIS spot curve, 6M maturity | L5: UK OIS spot curve, 12M maturity | M5: Shibor 1M | N5: Shibor 3M | O5: Shibor 6M | P5: Shibor 1Y | Q5: IR/B.KPRA.SD. | R5: SHORT_RATES/B.NOWA.ON.R | S5: SGS 432
A6: Description (quote direction) | B6: Secured Overnight Financing Rate (SOFR) | C6: Federal Funds Target Range - Upper Limit (DFEDTARU) | D6: Federal Funds Target Range - Lower Limit (DFEDTARL) | E6: Euro short-term rate | F6: Deposit facility - date of changes (raw data) - Level | G6: Official Bank Rate, daily | H6: Sterling Overnight Index Average, daily | I6: BoE estimated UK OIS (SONIA) spot rate, 1M maturity, continuously compounded per BoE methodology | J6: BoE estimated UK OIS (SONIA) spot rate, 3M maturity, continuously compounded per BoE methodology | K6: BoE estimated UK OIS (SONIA) spot rate, 6M maturity, continuously compounded per BoE methodology | L6: BoE estimated UK OIS (SONIA) spot rate, 12M maturity, continuously compounded per BoE methodology | M6: Shanghai Interbank Offered Rate, 1M tenor | N6: Shanghai Interbank Offered Rate, 3M tenor | O6: Shanghai Interbank Offered Rate, 6M tenor | P6: Shanghai Interbank Offered Rate, 1Y tenor | Q6: Key policy rate (sight deposit rate), daily | R6: Norwegian Overnight Weighted Average, daily | S6: Meta Selic definida pelo Copom (% a.a.)
A7: Unit | B7: Percent | C7: Percent | D7: Percent | E7: % p.a. | F7: % p.a. | G7: % p.a. | H7: % p.a. | I7: % p.a. | J7: % p.a. | K7: % p.a. | L7: % p.a. | M7: % p.a. | N7: % p.a. | O7: % p.a. | P7: % p.a. | Q7: % p.a. | R7: % p.a. | S7: % p.a.
A8: Frequency | B8: Daily | C8: Daily | D8: Daily | E8: Daily (TARGET days) | F8: Daily (calendar) | G8: Daily | H8: Daily | I8: Daily | J8: Daily | K8: Daily | L8: Daily | M8: Daily (China business days) | N8: Daily (China business days) | O8: Daily (China business days) | P8: Daily (China business days) | Q8: Daily | R8: Daily | S8: Daily
